Workbook

Sheet הנחות
A1: AHLAN קפה 150g — הנחות מודל (גרסה 3 המונעת בנוסחה)
A2: תאים כחולים = קלט | תאים שחורים = נוסחאות | צהוב = לאישור | כל הגיליונות מתעדכנים אוטומטית כשמשנים ערך כאן
A4: A. מוצר
A5: קלט | B5: ערך | C5: יחידה | D5: הערות / מקור
A6: עלות ייצור ל-100 גרם (מאושר — Rajuan) | B6: 3.7 | C6: ₪/100g | D6: הצעת מחיר מאושרת מהספק
A7: עלות ייצור ל-150 גרם (= עלות 100 גרם × 1.5) | B7: =הנחות!$B$6*1.5 | C7: ₪/150g | D7: נוסחה: =B6*1.5 | ₪3.70 × 1.5 = ₪5.55
A9: B. תמחור — המלצת מחיר B2B
A10: פרמטר | B10: ערך | C10: יחידה | D10: הערות
A11: שיעור מע״מ | B11: 0.18 | C11: % | D11: תקן ישראלי
A12: מרווח קמעונאי — רשתות מאורגנות (שופרסל...) | B12: 0.3 | C12: % | D12: מרווח קמעונאי טיפוסי ברשתות
A13: מרווח קמעונאי — שוק פרטי / ערוץ מעיין | B13: 0.2 | C13: % | D13: מרווח נמוך יותר בחנויות עצמאיות (שוק, מינימרקטים)
A14: עמלת הפצה מעיין | B14: 0.18 | C14: % | D14: טווח 15–25% — 18% תרחיש בסיס ⚠ לאשר עם מעיין
A15: מחיר B2B מומלץ ליחידה (Raito → שוק) | B15: 10.5 | C15: ₪/unit | D15: המלצת Claude — ראה כלכלת יחידה לנימוק מלא
A16: מחיר מדף B2C משתמע — קמעונאות מאורגנת (30% ret) | B16: =הנחות!$B$15/(1-הנחות!$B$12)*(1+הנחות!$B$11) | C16: ₪/unit | D16: לעיון בלבד — שוק פרטי הוא הערוץ העיקרי
A17: מחיר מדף B2C משתמע — שוק פרטי (20% ret) | B17: =הנחות!$B$15/(1-הנחות!$B$13)*(1+הנחות!$B$11) | C17: ₪/unit | D17: ערוץ עיקרי: מעיין → חנויות עצמאיות
A19: C. גודל שוק
A20: פרמטר | B20: ערך | C20: יחידה | D20: הערות / מקור
A21: שוק הקפה השחור הכולל (ערך B2C שנתי) | B21: 350000000 | C21: ₪/year | D21: גודל שוק מאושר — מקור: לקוח / תעשייה
A22: נתח שוק יעד AHLAN — דצמבר 2026 (קצב ריצה) | B22: 0.1 | C22: % | D22: יעד: 10% = ₪35M B2C שנתי בסוף העקומה
A23: הכנסות B2C שנתיות ביעד | B23: =הנחות!$B$21*הנחות!$B$22 | C23: ₪/year | D23: נוסחה: =הנחות!$B$21*הנחות!$B$22
A24: הכנסות B2C חודשיות ביעד (÷ 12) | B24: =הנחות!$B$21*הנחות!$B$22/12 | C24: ₪/month | D24: נוסחה: מעל/12
A25: מכפיל פאנל Store Next — נמוך | B25: 15 | C25: × | D25: Store Next מכסה רק קמעונאות מאורגנת; שוק פרטי מוסיף 15–20× יותר נקודות מכירה
A26: מכפיל פאנל Store Next — גבוה | B26: 20 | C26: × | D26: גבול עליון — משמש להקשר / אימות בלבד
A28: D. מקדמי תרחיש
A29: תרחיש | B29: מקדם | C29: נתח דצמ' 2026 | D29: תיאור
A30: שמרני | B30: 0.7 | C30: 7% דצמ' 26 → 8.4% דצמ' 27 | D30: שיווק מתחת לציפיות — עדיין חזק לעומת השקה ללא סלבריטי
A31: בסיס | B31: 1 | C31: 10% דצמ' 26 → 12% דצמ' 27 | D31: לפי תוכנית — קמפיין Ma Kashur מספק כמתוכנן (3 שלבים)
A32: אופטימי | B32: 1.3 | C32: 13% דצמ' 26 → 15.6% דצמ' 27 | D32: אימוץ ויראלי — תוכן Ma Kashur פורץ דרך; הפצה חזקה של מעיין
A34: E. עקומת צמיחה חודשית — בסיס (נתח שוק % — תרחיש בסיס; שמרני = ×0.70, אופטימי = ×1.30)
A35: חודש | B35: נתח בסיס % | D35: הערות
A36: Jul 2026 | B36: 0.05 | D36: השקה — קמפיין Ma Kashur + בליץ מדיה (שלב 2)
A37: Aug 2026 | B37: 0.065 | D37: תנופה לאחר השקה — דחיפה במדיה ורשתות חברתיות
A38: Sep 2026 | B38: 0.08 | D38: חדירת שוק — רשתות קמעונאיות + קיוסקים + תחנות דלק
A39: Oct 2026 | B39: 0.09 | D39: הרחבת הפצה ברחבי השוק הפרטי
A40: Nov 2026 | B40: 0.095 | D40: קרוב ליעד — בניית מודעות למותג
A41: Dec 2026 | B41: 0.1 | D41: יעד — הושג נתח שוק 10%
A42: Jan 2027 | B42: 0.1 | D42: שלב 3: תחילת בניית קהילה
A43: Feb 2027 | B43: 0.1 | D43: פלטפורמה דיגיטלית "פרלמנט הקפה"
A44: Mar 2027 | B44: 0.105 | D44: צמיחה עם נאמנות למותג
A45: Apr 2027 | B45: 0.105
...

Sheet כלכלת יחידה
A1: AHLAN קפה 150 גרם — כלכלת יחידה והמלצת מחיר B2B
A2: מחיר B2B ₪10.50 הוא המלצת Claude להשקה | כל הנוסחאות מתייחסות להנחות — שנה קלטים שם לחישוב מחדש | הכנסות Raito = חשבונית B2B; מעיין היא סוכן/מפיץ
A4: A. שרשרת תמחור בעלות B2B מומלצת של ₪10.50 (קמעונאות מאורגנת מול שוק פרטי)
A5: סעיף | B5: קמעונאות מאורגנת | C5: שוק פרטי | D5: נוסחה / הערות
A6: מחיר B2B — חשבונית Raito לשוק | B6: =הנחות!$B$15 | C6: =הנחות!$B$15 | D6: מומלץ: ₪10.50 | קלט בהנחות B15 | אותו B2B ללא תלות בערוץ
A7: מחיר מדף B2C משתמע (כולל 18% מע״מ) | B7: =הנחות!$B$15/(1-הנחות!$B$12)*(1+הנחות!$B$11) | C7: =הנחות!$B$15/(1-הנחות!$B$13)*(1+הנחות!$B$11) | D7: B2C = B2B / (1−ret%) × (1+VAT) | מאורגן: ₪17.70 | פרטי: ₪15.47
A8: ÷ (1 + מע״מ) — מחיר מדף ללא מע״מ | B8: =B7/(1+הנחות!$B$11) | C8: =C7/(1+הנחות!$B$11) | D8: הסר מע״מ לחישוב
A9: × (1 − מרווח קמעונאי) — B2B מאושר | B9: =B8*(1-הנחות!$B$12) | C9: =C8*(1-הנחות!$B$13) | D9: הנחת קמעונאי: 30% מאורגן / 20% שוק פרטי
A10: ► מחיר B2B (בדיקה צולבת — צריך להשתוות לשורה למעלה) | B10: =הנחות!$B$15 | C10: =הנחות!$B$15 | D10: בדיקה צולבת: שני הערוצים מניבים אותו מחיר B2B
A11: – עמלת מעיין (18% בסיס) | B11: =הנחות!$B$15*הנחות!$B$14 | C11: =הנחות!$B$15*הנחות!$B$14 | D11: טווח 15–25% | בסיס 18% | קלט: הנחות!$B$14 ⚠ אשר עם מעיין
A12: ► הכנסות נטו ל-Raito (לאחר מעיין) | B12: =הנחות!$B$15*(1-הנחות!$B$14) | C12: =הנחות!$B$15*(1-הנחות!$B$14) | D12: אותו דבר בשני הערוצים | ₪8.61 ב-B2B ₪10.50 / 18% עמלה
A13: – עלות ייצור 150 גרם (₪5.55 מאושר) | B13: =הנחות!$B$7 | C13: =הנחות!$B$7 | D13: Rajuan אישר ₪3.70/100 גרם × 1.5 = ₪5.55 | קלט: הנחות!$B$7
A14: ► רווח גולמי ליחידה | B14: =הנחות!$B$15*(1-הנחות!$B$14)-הנחות!$B$7 | C14: =הנחות!$B$15*(1-הנחות!$B$14)-הנחות!$B$7 | D14: הכנסות נטו פחות עלות ייצור
A15: שיעור רווח גולמי % (GP ÷ מחיר B2B) | B15: =IFERROR((הנחות!$B$15*(1-הנחות!$B$14)-הנחות!$B$7)/הנחות!$B$15,0) | C15: =IFERROR((הנחות!$B$15*(1-הנחות!$B$14)-הנחות!$B$7)/הנחות!$B$15,0) | D15: GP / מחיר B2B | יעד: 29%+ ב-18% עמלה
A17: B. מדוע B2B ₪10.50 — נימוק ההמלצה
A18: גורם | B18: נתון | C18: משמעות
A19: אמת מידה תחרותית | B19: Elite 150g ממוצע B2C ₪13.14 (נתוני CHP, 8 רשתות בלבד) — כמעט לא זמין | C19: CHP מאשר: רק 8/94 רשתות מוכרות 150 גרם → רווח לבן עשיר. AHLAN ב-₪15.47 B2C מתחרה אפילו עם תמחור מאורגן
A20: כדאיות רווח גולמי | B20: ב-B2B ₪10.50 / 18% עמלה: GP = ₪3.06 / יחידה (35.5% GM) | C20: מרווח מינימלי כדאי לברנד מעורר — מספיק לשקעון מחדש בהפצה
A21: מבנה עלויות | B21: ייצור ₪5.55 / יחידה (₪3.70/100g × 1.5 — מאושר ע״י Rajuan) | C21: בסיס עלות נמוך יוצר גמישות תמחור אם B2B צריך להתאים למטה
A22: מסלול ל-₪11.50+ | B22: לאחר השגת 10% נתח שוק, העלאת B2B ל-₪11.50 → 41% GM | C22: השקה בעדיפות נפח ב-₪10.50, ואז שיפור רווח לאחר נעילת הפצה
A23: מיצוב מול Elite | B23: CHP: Elite 150 גרם ממוצע ₪13.14 (8 רשתות) | 200 גרם ממוצע ₪19.25 (72 רשתות) | 100 גרם ממוצע ₪11.53 (66 רשתות) | C23: AHLAN 150 גרם ב-₪15.47 = פרמיום ל-Elite 150 גרם דל אך מתחת ל-200 גרם — נקודת הכושר של השוק הפרטי
A25: C. רגישות עמלת הפצה (ב-B2B ₪10.50)
A26: עמלת מעיין | B26: נטו ל-Raito | C26: רווח גולמי/יחידה | D26: שיעור רווח גולמי % | E26: הערה
A27: 0.15 | B27: =הנחות!$B$15*(1-0.15) | C27: =הנחות!$B$15*(1-0.15)-הנחות!$B$7 | D27: =IFERROR((הנחות!$B$15*(1-0.15)-הנחות!$B$7)/הנחות!$B$15,0) | E27: נמוך — לטובתנו
A28: 0.18 | B28: =הנחות!$B$15*(1-0.18) | C28: =הנחות!$B$15*(1-0.18)-הנחות!$B$7 | D28: =IFERROR((הנחות!$B$15*(1-0.18)-הנחות!$B$7)/הנחות!$B$15,0) | E28: תרחיש בסיס ✓
A29: 0.2 | B29: =הנחות!$B$15*(1-0.2) | C29: =הנחות!$B$15*(1-0.2)-הנחות!$B$7 | D29: =IFERROR((הנחות!$B$15*(1-0.2)-הנחות!$B$7)/הנחות!$B$15,0) | E29: גבוה — לנהל מו״מ להורדה
A30: 0.22 | B30: =הנחות!$B$15*(1-0.22) | C30: =הנחות!$B$15*(1-0.22)-הנחות!$B$7 | D30: =IFERROR((הנחות!$B$15*(1-0.22)-הנחות!$B$7)/הנחות!$B$15,0) | E30: גבוה — לנהל מו״מ להורדה
A31: 0.25 | B31: =הנחות!$B$15*(1-0.25) | C31: =הנחות!$B$15*(1-0.25)-הנחות!$B$7 | D31: =IFERROR((הנחות!$B$15*(1-0.25)-הנחות!$B$7)/הנחות!$B$15,0) | E31: גבוה — לנהל מו״מ להורדה

Sheet תחזית מכירות
A1: AHLAN קפה 150 גרם — תחזית מכירות (גישה מלמעלה: שוק × נתח% → הכנסות → יחידות)
A2: שוק: ₪350M סה״כ קפה שחור (B2C, כל הערוצים) | B2B: ₪10.50 | מעיין: 18% | שותפים מייסדים של Ma Kashur → השקה חזקה + צמיחה בשנת 2027 | תרחישים: ×0.70 / ×1.00 / ×1.30 על עקומת בסיס
A4: תרחיש 1: שמרני — 7% נתח דצמ' 2026 → ~8.4% דצמ' 2027 | שיווק מתחת לציפיות
A5: מחיר B2B: ₪10.50 | מקדם: הנחות!$B$30 × עקומת בסיס | שוק: הנחות!$B$21 | עמלת מעיין: הנחות!$B$14
A6: חודש | B6: נתח שוק % | C6: הכנסות B2C חודשיות (₪) | D6: יחידות שנמכרו | E6: הכנסות B2B (₪) | F6: עמלת מעיין (₪) | G6: הכנסות נטו ל-Raito (₪) | H6: עלות המכר (₪) | I6: רווח גולמי (₪) | J6: רווח גולמי % (GP/B2B) | K6: מצטבר יחידות | L6: מצטבר הכנסות נטו (₪)
A7: Jul 2026 | B7: =הנחות!$B$36*הנחות!$B$30 | C7: =(הנחות!$B$21/12)*B7 | D7: =ROUND(C7*(1-הנחות!$B$13)/(הנחות!$B$15*(1+הנחות!$B$11)),0) | E7: =D7*הנחות!$B$15 | F7: =E7*הנחות!$B$14 | G7: =E7*(1-הנחות!$B$14) | H7: =D7*הנחות!$B$7 | I7: =G7-H7 | J7: =IFERROR(I7/E7,0) | K7: =D7 | L7: =G7
A8: Aug 2026 | B8: =הנחות!$B$37*הנחות!$B$30 | C8: =(הנחות!$B$21/12)*B8 | D8: =ROUND(C8*(1-הנחות!$B$13)/(הנחות!$B$15*(1+הנחות!$B$11)),0) | E8: =D8*הנחות!$B$15 | F8: =E8*הנחות!$B$14 | G8: =E8*(1-הנחות!$B$14) | H8: =D8*הנחות!$B$7 | I8: =G8-H8 | J8: =IFERROR(I8/E8,0) | K8: =K7+D8 | L8: =L7+G8
A9: Sep 2026 | B9: =הנחות!$B$38*הנחות!$B$30 | C9: =(הנחות!$B$21/12)*B9 | D9: =ROUND(C9*(1-הנחות!$B$13)/(הנחות!$B$15*(1+הנחות!$B$11)),0) | E9: =D9*הנחות!$B$15 | F9: =E9*הנחות!$B$14 | G9: =E9*(1-הנחות!$B$14) | H9: =D9*הנחות!$B$7 | I9: =G9-H9 | J9: =IFERROR(I9/E9,0) | K9: =K8+D9 | L9: =L8+G9
A10: Oct 2026 | B10: =הנחות!$B$39*הנחות!$B$30 | C10: =(הנחות!$B$21/12)*B10 | D10: =ROUND(C10*(1-הנחות!$B$13)/(הנחות!$B$15*(1+הנחות!$B$11)),0) | E10: =D10*הנחות!$B$15 | F10: =E10*הנחות!$B$14 | G10: =E10*(1-הנחות!$B$14) | H10: =D10*הנחות!$B$7 | I10: =G10-H10 | J10: =IFERROR(I10/E10,0) | K10: =K9+D10 | L10: =L9+G10
A11: Nov 2026 | B11: =הנחות!$B$40*הנחות!$B$30 | C11: =(הנחות!$B$21/12)*B11 | D11: =ROUND(C11*(1-הנחות!$B$13)/(הנחות!$B$15*(1+הנחות!$B$11)),0) | E11: =D11*הנחות!$B$15 | F11: =E11*הנחות!$B$14 | G11: =E11*(1-הנחות!$B$14) | H11: =D11*הנחות!$B$7 | I11: =G11-H11 | J11: =IFERROR(I11/E11,0) | K11: =K10+D11 | L11: =L10+G11
A12: Dec 2026 | B12: =הנחות!$B$41*הנחות!$B$30 | C12: =(הנחות!$B$21/12)*B12 | D12: =ROUND(C12*(1-הנחות!$B$13)/(הנחות!$B$15*(1+הנחות!$B$11)),0) | E12: =D12*הנחות!$B$15 | F12: =E12*הנחות!$B$14 | G12: =E12*(1-הנחות!$B$14) | H12: =D12*הנחות!$B$7 | I12: =G12-H12 | J12: =IFERROR(I12/E12,0) | K12: =K11+D12 | L12: =L11+G12
A13: Jan 2027 | B13: =הנחות!$B$42*הנחות!$B$30 | C13: =(הנחות!$B$21/12)*B13 | D13: =ROUND(C13*(1-הנחות!$B$13)/(הנחות!$B$15*(1+הנחות!$B$11)),0) | E13: =D13*הנחות!$B$15 | F13: =E13*הנחות!$B$14 | G13: =E13*(1-הנחות!$B$14) | H13: =D13*הנחות!$B$7 | I13: =G13-H13 | J13: =IFERROR(I13/E13,0) | K13: =K12+D13 | L13: =L12+G13
A14: Feb 2027 | B14: =הנחות!$B$43*הנחות!$B$30 | C14: =(הנחות!$B$21/12)*B14 | D14: =ROUND(C14*(1-הנחות!$B$13)/(הנחות!$B$15*(1+הנחות!$B$11)),0) | E14: =D14*הנחות!$B$15 | F14: =E14*הנחות!$B$14 | G14: =E14*(1-הנחות!$B$14) | H14: =D14*הנחות!$B$7 | I14: =G14-H14 | J14: =IFERROR(I14/E14,0) | K14: =K13+D14 | L14: =L13+G14
A15: Mar 2027 | B15: =הנחות!$B$44*הנחות!$B$30 | C15: =(הנחות!$B$21/12)*B15 | D15: =ROUND(C15*(1-הנחות!$B$13)/(הנחות!$B$15*(1+הנחות!$B$11)),0) | E15: =D15*הנחות!$B$15 | F15: =E15*הנחות!$B$14 | G15: =E15*(1-הנחות!$B$14) | H15: =D15*הנחות!$B$7 | I15: =G15-H15 | J15: =IFERROR(I15/E15,0) | K15: =K14+D15 | L15: =L14+G15
A16: Apr 2027 | B16: =הנחות!$B$45*הנחות!$B$30 | C16: =(הנחות!$B$21/12)*B16 | D16: =ROUND(C16*(1-הנחות!$B$13)/(הנחות!$B$15*(1+הנחות!$B$11)),0) | E16: =D16*הנחות!$B$15 | F16: =E16*הנחות!$B$14 | G16: =E16*(1-הנחות!$B$14) | H16: =D16*הנחות!$B$7 | I16: =G16-H16 | J16: =IFERROR(I16/E16,0) | K16: =K15+D16 | L16: =L15+G16
A17: May 2027 | B17: =הנחות!$B$46*הנחות!$B$30 | C17: =(הנחות!$B$21/12)*B17 | D17: =ROUND(C17*(1-הנחות!$B$13)/(הנחות!$B$15*(1+הנחות!$B$11)),0) | E17: =D17*הנחות!$B$15 | F17: =E17*הנחות!$B$14 | G17: =E17*(1-הנחות!$B$14) | H17: =D17*הנחות!$B$7 | I17: =G17-H17 | J17: =IFERROR(I17/E17,0) | K17: =K16+D17 | L17: =L16+G17
A18: Jun 2027 | B18: =הנחות!$B$47*הנחות!$B$30 | C18: =(הנחות!$B$21/12)*B18 | D18: =ROUND(C18*(1-הנחות!$B$13)/(הנחות!$B$15*(1+הנחות!$B$11)),0) | E18: =D18*הנחות!$B$15 | F18: =E18*הנחות!$B$14 | G18: =E18*(1-הנחות!$B$14) | H18: =D18*הנחות!$B$7 | I18: =G18-H18 | J18: =IFERROR(I18/E18,0) | K18: =K17+D18 | L18: =L17+G18
A19: Jul 2027 | B19: =הנחות!$B$48*הנחות!$B$30 | C19: =(הנחות!$B$21/12)*B19 | D19: =ROUND(C19*(1-הנחות!$B$13)/(הנחות!$B$15*(1+הנחות!$B$11)),0) | E19: =D19*הנחות!$B$15 | F19: =E19*הנחות!$B$14 | G19: =E19*(1-הנחות!$B$14) | H19: =D19*הנחות!$B$7 | I19: =G19-H19 | J19: =IFERROR(I19/E19,0) | K19: =K18+D19 | L19: =L18+G19
A20: Aug 2027 | B20: =הנחות!$B$49*הנחות!$B$30 | C20: =(הנחות!$B$21/12)*B20 | D20: =ROUND(C20*(1-הנחות!$B$13)/(הנחות!$B$15*(1+הנחות!$B$11)),0) | E20: =D20*הנחות!$B$15 | F20: =E20*הנחות!$B$14 | G20: =E20*(1-הנחות!$B$14) | H20: =D20*הנחות!$B$7 | I20: =G20-H20 | J20: =IFERROR(I20/E20,0) | K20: =K19+D20 | L20: =L19+G20
A21: Sep 2027 | B21: =הנחות!$B$50*הנחות!$B$30 | C21: =(הנחות!$B$21/12)*B21 | D21: =ROUND(C21*(1-הנחות!$B$13)/(הנחות!$B$15*(1+הנחות!$B$11)),0) | E21: =D21*הנחות!$B$15 | F21: =E21*הנחות!$B$14 | G21: =E21*(1-הנחות!$B$14) | H21: =D21*הנחות!$B$7 | I21: =G21-H21 | J21: =IFERROR(I21/E21,0) | K21: =K20+D21 | L21: =L20+G21
A22: Oct 2027 | B22: =הנחות!$B$51*הנחות!$B$30 | C22: =(הנחות!$B$21/12)*B22 | D22: =ROUND(C22*(1-הנחות!$B$13)/(הנחות!$B$15*(1+הנחות!$B$11)),0) | E22: =D22*הנחות!$B$15 | F22: =E22*הנחות!$B$14 | G22: =E22*(1-הנחות!$B$14) | H22: =D22*הנחות!$B$7 | I22: =G22-H22 | J22: =IFERROR(I22/E22,0) | K22: =K21+D22 | L22: =L21+G22
A23: Nov 2027 | B23: =הנחות!$B$52*הנחות!$B$30 | C23: =(הנחות!$B$21/12)*B23 | D23: =ROUND(C23*(1-הנחות!$B$13)/(הנחות!$B$15*(1+הנחות!$B$11)),0) | E23: =D23*הנחות!$B$15 | F23: =E23*הנחות!$B$14 | G23: =E23*(1-הנחות!$B$14) | H23: =D23*הנחות!$B$7 | I23: =G23-H23 | J23: =IFERROR(I23/E23,0) | K23: =K22+D23 | L23: =L22+G23
A24: Dec 2027 | B24: =הנחות!$B$53*הנחות!$B$30 | C24: =(הנחות!$B$21/12)*B24 | D24: =ROUND(C24*(1-הנחות!$B$13)/(הנחות!$B$15*(1+הנחות!$B$11)),0) | E24: =D24*הנחות!$B$15 | F24: =E24*הנחות!$B$14 | G24: =E24*(1-הנחות!$B$14) | H24: =D24*הנחות!$B$7 | I24: =G24-H24 | J24: =IFERROR(I24/E24,0) | K24: =K23+D24 | L24: =L23+G24
A25: H1-2026 (יול׳–דצמ׳ 2026) | C25: =SUM(C7:C12) | D25: =SUM(D7:D12) | E25: =SUM(E7:E12) | F25: =SUM(F7:F12) | G25: =SUM(G7:G12) | H25: =SUM(H7:H12) | I25: =SUM(I7:I12) | J25: =IFERROR(SUM(I7:I12)/SUM(E7:E12),0)
A26: H1-2027 (ינו׳–יונ׳ 2027) | C26: =SUM(C13:C18) | D26: =SUM(D13:D18) | E26: =SUM(E13:E18) | F26: =SUM(F13:F18) | G26: =SUM(G13:G18) | H26: =SUM(H13:H18) | I26: =SUM(I13:I18) | J26: =IFERROR(SUM(I13:I18)/SUM(E13:E18),0)
A27: H2-2027 (יול׳–דצמ׳ 2027) | C27: =SUM(C19:C24) | D27: =SUM(D19:D24) | E27: =SUM(E19:E24) | F27: =SUM(F19:F24) | G27: =SUM(G19:G24) | H27: =SUM(H19:H24) | I27: =SUM(I19:I24) | J27: =IFERROR(SUM(I19:I24)/SUM(E19:E24),0)
A28: סה״כ (יול׳ 2026 – דצמ׳ 2027) | C28: =SUM(C7:C24) | D28: =SUM(D7:D24) | E28: =SUM(E7:E24) | F28: =SUM(F7:F24) | G28: =SUM(G7:G24) | H28: =SUM(H7:H24) | I28: =SUM(I7:I24) | J28: =IFERROR(SUM(I7:I24)/SUM(E7:E24),0)
A30: תרחיש 2: בסיס — 10% נתח דצמ' 2026 → 12% דצמ' 2027 | קמפיין Ma Kashur לפי תוכנית ◄ תוכנית
A31: מחיר B2B: ₪10.50 | מקדם: הנחות!$B$31 × עקומת בסיס | שוק: הנחות!$B$21 | עמלת מעיין: הנחות!$B$14
A32: חודש | B32: נתח שוק % | C32: הכנסות B2C חודשיות (₪) | D32: יחידות שנמכרו | E32: הכנסות B2B (₪) | F32: עמלת מעיין (₪) | G32: הכנסות נטו ל-Raito (₪) | H32: עלות המכר (₪) | I32: רווח גולמי (₪) | J32: רווח גולמי % (GP/B2B) | K32: מצטבר יחידות | L32: מצטבר הכנסות נטו (₪)
A33: Jul 2026 | B33: =הנחות!$B$36*הנחות!$B$31 | C33: =(הנחות!$B$21/12)*B33 | D33: =ROUND(C33*(1-הנחות!$B$13)/(הנחות!$B$15*(1+הנחות!$B$11)),0) | E33: =D33*הנחות!$B$15 | F33: =E33*הנחות!$B$14 | G33: =E33*(1-הנחות!$B$14) | H33: =D33*הנחות!$B$7 | I33: =G33-H33 | J33: =IFERROR(I33/E33,0) | K33: =D33 | L33: =G33
A34: Aug 2026 | B34: =הנחות!$B$37*הנחות!$B$31 | C34: =(הנחות!$B$21/12)*B34 | D34: =ROUND(C34*(1-הנחות!$B$13)/(הנחות!$B$15*(1+הנחות!$B$11)),0) | E34: =D34*הנחות!$B$15 | F34: =E34*הנחות!$B$14 | G34: =E34*(1-הנחות!$B$14) | H34: =D34*הנחות!$B$7 | I34: =G34-H34 | J34: =IFERROR(I34/E34,0) | K34: =K33+D34 | L34: =L33+G34
A35: Sep 2026 | B35: =הנחות!$B$38*הנחות!$B$31 | C35: =(הנחות!$B$21/12)*B35 | D35: =ROUND(C35*(1-הנחות!$B$13)/(הנחות!$B$15*(1+הנחות!$B$11)),0) | E35: =D35*הנחות!$B$15 | F35: =E35*הנחות!$B$14 | G35: =E35*(1-הנחות!$B$14) | H35: =D35*הנחות!$B$7 | I35: =G35-H35 | J35: =IFERROR(I35/E35,0) | K35: =K34+D35 | L35: =L34+G35
A36: Oct 2026 | B36: =הנחות!$B$39*הנחות!$B$31 | C36: =(הנחות!$B$21/12)*B36 | D36: =ROUND(C36*(1-הנחות!$B$13)/(הנחות!$B$15*(1+הנחות!$B$11)),0) | E36: =D36*הנחות!$B$15 | F36: =E36*הנחות!$B$14 | G36: =E36*(1-הנחות!$B$14) | H36: =D36*הנחות!$B$7 | I36: =G36-H36 | J36: =IFERROR(I36/E36,0) | K36: =K35+D36 | L36: =L35+G36
A37: Nov 2026 | B37: =הנחות!$B$40*הנחות!$B$31 | C37: =(הנחות!$B$21/12)*B37 | D37: =ROUND(C37*(1-הנחות!$B$13)/(הנחות!$B$15*(1+הנחות!$B$11)),0) | E37: =D37*הנחות!$B$15 | F37: =E37*הנחות!$B$14 | G37: =E37*(1-הנחות!$B$14) | H37: =D37*הנחות!$B$7 | I37: =G37-H37 | J37: =IFERROR(I37/E37,0) | K37: =K36+D37 | L37: =L36+G37
A38: Dec 2026 | B38: =הנחות!$B$41*הנחות!$B$31 | C38: =(הנחות!$B$21/12)*B38 | D38: =ROUND(C38*(1-הנחות!$B$13)/(הנחות!$B$15*(1+הנחות!$B$11)),0) | E38: =D38*הנחות!$B$15 | F38: =E38*הנחות!$B$14 | G38: =E38*(1-הנחות!$B$14) | H38: =D38*הנחות!$B$7 | I38: =G38-H38 | J38: =IFERROR(I38/E38,0) | K38: =K37+D38 | L38: =L37+G38
A39: Jan 2027 | B39: =הנחות!$B$42*הנחות!$B$31 | C39: =(הנחות!$B$21/12)*B39 | D39: =ROUND(C39*(1-הנחות!$B$13)/(הנחות!$B$15*(1+הנחות!$B$11)),0) | E39: =D39*הנחות!$B$15 | F39: =E39*הנחות!$B$14 | G39: =E39*(1-הנחות!$B$14) | H39: =D39*הנחות!$B$7 | I39: =G39-H39 | J39: =IFERROR(I39/E39,0) | K39: =K38+D39 | L39: =L38+G39
A40: Feb 2027 | B40: =הנחות!$B$43*הנחות!$B$31 | C40: =(הנחות!$B$21/12)*B40 | D40: =ROUND(C40*(1-הנחות!$B$13)/(הנחות!$B$15*(1+הנחות!$B$11)),0) | E40: =D40*הנחות!$B$15 | F40: =E40*הנחות!$B$14 | G40: =E40*(1-הנחות!$B$14) | H40: =D40*הנחות!$B$7 | I40: =G40-H40 | J40: =IFERROR(I40/E40,0) | K40: =K39+D40 | L40: =L39+G40
A41: Mar 2027 | B41: =הנחות!$B$44*הנחות!$B$31 | C41: =(הנחות!$B$21/12)*B41 | D41: =ROUND(C41*(1-הנחות!$B$13)/(הנחות!$B$15*(1+הנחות!$B$11)),0) | E41: =D41*הנחות!$B$15 | F41: =E41*הנחות!$B$14 | G41: =E41*(1-הנחות!$B$14) | H41: =D41*הנחות!$B$7 | I41: =G41-H41 | J41: =IFERROR(I41/E41,0) | K41: =K40+D41 | L41: =L40+G41
A42: Apr 2027 | B42: =הנחות!$B$45*הנחות!$B$31 | C42: =(הנחות!$B$21/12)*B42 | D42: =ROUND(C42*(1-הנחות!$B$13)/(הנחות!$B$15*(1+הנחות!$B$11)),0) | E42: =D42*הנחות!$B$15 | F42: =E42*הנחות!$B$14 | G42: =E42*(1-הנחות!$B$14) | H42: =D42*הנחות!$B$7 | I42: =G42-H42 | J42: =IFERROR(I42/E42,0) | K42: =K41+D42 | L42: =L41+G42
...

Sheet ניתוח שוק
A1: AHLAN קפה — ניתוח שוק (קטגוריית קפה שחור ישראלית)
A2: שוק כולל: ₪350M (כל הערוצים) | פאנל Store Next = תת-קבוצה של קמעונאות מאורגנת בלבד (~2,600 נקודות מכירה) | שוק פרטי (ערוץ מעיין) יש 15×–20× יותר נקודות מכירה שלא נתפסו על ידי Store Next
A4: A. STORE NEXT — מכירות יחידות (אלפים) ⚠ פאנל קמעונאות מאורגנת בלבד (אינו מייצג את מלוא שוק ה-₪350M)
A5: מוצר / SKU | B5: 2024 | C5: 2025 | D5: 2026 עד תאריך | E5: מצטבר 2025 | F5: מצטבר 2026 | G5: הערות
A6: סה״כ קטגוריית קפה שחור | B6: 19083.3 | C6: 18472.1 | D6: 3434.74 | E6: 3037.3 | F6: 3074.75 | G6: סה״כ פאנל קמעונאות מאורגנת, כל ה-SKUs
A7: Elite 200 גרם (מוביל שוק) | B7: 4649.19 | C7: 3875.63 | D7: 896.31 | E7: 777.06 | F7: 815.73 | G7: ירידה ביחידות 2025 לעומת 2024
A8: Elite 100g | B8: 2547.96 | C8: 2172.19 | D8: 399.78 | E8: 397.36 | F8: 366.81 | G8: ירידה קלה
A9: Elite 150 גרם ★ הסגמנט של AHLAN ★ | B9: 526.19 | C9: 1124.84 | D9: 235.48 | E9: 140.71 | F9: 210.18 | G9: הוכפל ב-2025! +113% יחידות שנתי — ה-SKU הצומח ביותר
A10: Elite 85g | B10: 1380.69 | C10: 1106.28 | D10: 154.1 | E10: 218.39 | F10: 135.52 | G10: בירידה
A11: Elite דרך 168 גרם | B11: 526.38 | C11: 660.33 | D11: 136.83 | E11: 110.24 | F11: 123.6 | G11: צמיחה מתונה
A12: Elite 3×85 גרם רב-חבילה | B12: 1119.26 | C12: 945.32 | D12: 121.69 | E12: 102.69 | F12: 102.36 | G12: בירידה
A13: Elite 100 גרם עם הל | B13: 665.25 | C13: 666.17 | D13: 126.28 | E13: 111.3 | F13: 111.98 | G13: יציב
A14: Elite 98 גרם×3 (חדש 2026) | B14: - | C14: 0.08 | D14: 119.27 | E14: - | F14: 116.84 | G14: כניסה חדשה 2026 — השקה מהירה
A16: B. STORE NEXT — ערך ונתח שוק ⚠ פאנל בלבד (₪M סיכומים; פריטים = נתח בתוך הפאנל; לא השוק הכולל)
A17: מוצר / SKU | B17: 2024 | C17: 2025 | D17: 2026 עד תאריך | E17: מצטבר 2025 | F17: מצטבר 2026 | G17: שינוי
A18: ערך שוק כולל (₪M) | B18: 303.71 | C18: 343.42 | D18: 65.07 | E18: 53.83 | F18: 58.19 | G18: +8.1%
A19: Elite 200g — נתח | B19: 0.242 | C19: 0.204 | D19: 0.247 | E19: 0.26 | F19: 0.251 | G19: +4.2%
A20: Elite 100g — נתח | B20: 0.078 | C20: 0.071 | D20: 0.07 | E20: 0.08 | F20: 0.071 | G20: -3.7%
A21: Elite 150 גרם ★ — נתח | B21: 0.022 | C21: 0.045 | D21: 0.051 | E21: 0.036 | F21: 0.051 | G21: +52.4% !!
A22: Elite 3×125g — נתח | B22: 0.077 | C22: 0.076 | D22: 0.051 | E22: 0.045 | F22: 0.05 | G22: +21.7%
A23: Elite 4×100g — נתח | B23: 0.08 | C23: 0.054 | D23: 0.046 | E23: 0.053 | F23: 0.045 | G23: -8.8%
A24: Elite 3×85g — נתח | B24: 0.07 | C24: 0.063 | D24: 0.045 | E24: 0.042 | F24: 0.042 | G24: —
A25: Elite 4×115g (חדש 2026) — נתח | B25: — | C25: — | D25: 0.059 | E25: — | F25: 0.059 | G25: —
A26: Elite 98g×3 (חדש) — נתח | B26: — | C26: 0 | D26: 0.043 | E26: — | F26: 0.047 | G26: —
A28: C. ניסוח בדוק של גודל שוק — מסלול מ-₪350M ל-AHLAN ₪35M
A29: Metric | B29: ערך | C29: הערות
A30: שוק קפה שחור כולל (B2C שנתי) | B30: =הנחות!$B$21 | C30: מאושר — משמש כעוגן מודל
A31: נתח שוק יעד AHLAN — דצמבר 2026 (קצב ריצה) | B31: =הנחות!$B$22 | C31: הגעה ל-10% עד דצמבר 2026
A32: הכנסות B2C שנתיות של AHLAN ביעד | B32: =הנחות!$B$21*הנחות!$B$22 | C32: ₪35M שנתי
A33: AHLAN B2C חודשי במטרה מלאה | B33: =הנחות!$B$21*הנחות!$B$22/12 | C33: ₪2.92M לחודש בקצב ריצה דצמבר 2026
A34: יחידות משתמעות לחודש במטרה (B2C ÷ מחיר B2C משתמע) | B34: =הנחות!$B$21*הנחות!$B$22/12*(1-הנחות!$B$13)/(הנחות!$B$15*(1+הנחות!$B$11)) | C34: ~188K יחידות לחודש ב-₪10.50 B2B / 20% קמעונאות שוק פרטי
A35: קטע Store Next 150 גרם (קמעונאות מאורגנת 2025) | B35: 15450000 | C35: 4.5% × ₪343.42M פאנל — קמעונאות מאורגנת בלבד
A36: קטע 150 גרם עם שוק פרטי (×17.5 אומד.) | B36: =B35*(הנחות!$B$25+הנחות!$B$26)/2 | C36: Store Next 150 גרם × מכפיל נקודת אמצע 17.5×
A37: יעד AHLAN לעומת קטע 150 גרם + פרטי | B37: =הנחות!$B$21*הנחות!$B$22/B36 | C37: AHLAN ₪35M כנתח של שוק כולל 150 גרם משוער
A39: D. טרנד קטע 150g — למה 150g הוא ה-SKU הנכון להשקה עכשיו
A40: Metric | B40: Data | D40: Insight
A41: יחידות Elite 150g 2024 → 2025 | B41: 526K → 1,125K (+113%) | D41: יותר מהוכפל בשנה — גודל הצומח ביותר בקטגוריה
A42: נתח ערך Elite 150g 2024→2025 | B42: 2.2% → 4.5% | D42: השוק משנה באופן פעיל נפח לכיוון גודל חבילה 150g
A43: YTD 2026 לעומת אותה תקופה 2025 | B43: 210K vs 141K (+49%) | D43: תנופת גדילה ממשיכה ל-2026 — קטגוריה לא מאטה
A44: טרנד Elite 200g | B44: בירידה (3,875K → store-level pressure) | D44: צרכנים מתרחקים מ-200g — 150g היא התבנית המתעוררת
...

Sheet מודיעין שוק CHP
A1: מודיעין שוק CHP — קמעונאות מאורגנת ישראלית (94 רשתות, 2,194 חנויות)
A2: נתוני פאנל CHP: 19 מרץ 2026 | תמחור ונפיצות תחרותית SKU קפה שחור Elite | כיסוי: רשתות מאורגנות בלבד (לא כולל שוק פרטי — המוקד העיקרי של AHLAN)
A4: A. תמחור תחרותי — Elite Turkish Coffee SKUs (נתוני CHP, 19 במרץ 2026)
A5: SKU | B5: מחיר B2C ממוצע (₪) | C5: מחיר מינימום (₪) | D5: מחיר מקסימום (₪) | E5: רשתות עם מחיר | F5: % מ-94 רשתות | G5: מחיר ל-100 גרם (₪)
A6: Elite 200g | B6: 19.25 | C6: 14.9 | D6: 23.5 | E6: 72 | F6: 0.766 | G6: 9.63
A7: Elite 100g | B7: 11.53 | C7: 5.9 | D7: 14.9 | E7: 66 | F7: 0.702 | G7: 11.53
A8: Elite 150g | B8: 13.14 | C8: 12.1 | D8: 14.9 | E8: 8 | F8: 0.085 | G8: 8.76
A9: Elite 7x24 גרם דרך | B9: 20.83 | C9: 14.9 | D9: 27.9 | E9: 75 | F9: 0.798 | G9: 12.4
A10: Elite 85g | B10: 9.12 | C10: 8.2 | D10: 9.9 | E10: 6 | F10: 0.064 | G10: 10.73
A11: Elite 3x85g | B11: 24.46 | C11: 19.9 | D11: 32.9 | E11: 51 | F11: 0.543 | G11: 9.59
A12: AHLAN 150 גרם (שוק פרטי) | B12: =הנחות!$B$15/(1-הנחות!$B$13)*(1+הנחות!$B$11) | C12: TBD | D12: TBD | E12: — | F12: — | G12: =B12/1.5
A14: תובנת תמחור: Elite 150g ב-₪8.76/100 גרם היא האפשרות הזולה ביותר ל-100 גרם — הצעת ערך거대
A15: AHLAN ב-~₪10.31/100 גרם (B2C ₪15.47 / 150g) היא בין Elite 200g ל-100g לגרם — תחרותית
A16: רק 8/94 רשתות אפילו מוכרות Elite 150g — מרווח לבן ענק ל-AHLAN למלא
A18: B. זיקה הפצה — פאנל CHP (2,194 חנויות, 94 רשתות)
A19: SKU | B19: סה״כ חנויות | C19: חנויות מוכרות | D19: % נפיצות | E19: רשתות פעילות | F19: פער הזדמנות
A20: Elite 200g | B20: 2194 | C20: 1327 | D20: 0.605 | E20: 72 / 94 | F20: מוביל שוק — אמת מידה
A21: Elite 100g | B21: 2194 | C21: 1464 | D21: 0.667 | E21: 66 / 94 | F21: הפצה גבוהה ביותר
A22: Elite 150g | B22: 2194 | C22: 23 | D22: 0.0105 | E22: 8 / 94 | F22: ★ פער ענק — כמעט לא קיים בקמעונאות ★
A23: Elite 7x24g Travel | B23: 2194 | C23: 1006 | D23: 0.459 | E23: 75 / 94 | F23: תבנית נסיעה — סגמנט שונה
A24: Elite 85g | B24: 2194 | C24: 31 | D24: 0.014 | E24: 6 / 94 | F24: גם זניח
A25: Elite 3x85g | B25: 2194 | C25: 778 | D25: 0.355 | E25: 51 / 94 | F25: סגמנט מולטי-חבילה
A27: ★ מציאה קרִיטית: Elite 150g יש הפצה של 1% בלבד (23 מתוך 2,194 חנויות) למרות הכפלה במכירות Store Next
A28: זה אומר שביקוש 150g משמש על ידי חלק זעום של חנויות — ביקוש עדור קיים בכל השוק
A29: הזדמנות AHLAN: כנס לקטע 150g דרך שוק הפרטי של מעיין שבו ל-Elite אין נוכחות מאורגנת ZERO
A30: CHP מכסה 2,194 חנויות (רחב יותר מ-Store Next ~2,600) — מאשר שפער ההפצה אמיתי בכל הפנלים
A32: C. ניתוח זמינות וחוסר מלאי (חנויות ללא פעילות בקופה)
A33: SKU | B33: חנויות עם חוסר | C33: הערות
A34: Elite 200g | B34: 146 | C34: חוסר משמעותי למוביל שוק
A35: Elite 100g | B35: 145 | C35: רמה דומה של בעיות אספקה
A36: Elite 150g | B36: 47 | C36: מוחלט נמוך — אבל 150g רק בחנויות ~70 שנרשמו אי פעם → ~67% שיעור חוסר!
A37: Elite 7x24g Travel | B37: 167 | C37: חוסרים גבוהים ביותר — בעיות שרשרת אספקה?
A38: Elite 85g | B38: 52 | C38: מתון
A39: Elite 3x85g | B39: 125 | C39: משמעותי
A41: שיעור החוסר של Elite 150g מרמז ש-~67% מהחנויות שאי פעם מכרו הפסיקו למכור — בעיית אספקה/תשומת לב מ-Strauss, לא בעיית ביקוש
A43: רשתות מובילות לפי ספירת חוסר (כל ה-SKUs):
A44: Yellow | B44: 183 | C44: חנויות עם חוסר/אי-מכירה
A45: Carrefour City | B45: 50 | C45: חנויות עם חוסר/אי-מכירה
A46: Super Yuda | B46: 48 | C46: חנויות עם חוסר/אי-מכירה
A47: נתיב החסד | B47: 25 | C47: חנויות עם חוסר/אי-מכירה
...

Sheet סיכום רווח והפסד
A1: AHLAN קפה 150 גרם — סיכום רווח והפסד (הכנסות B2B כשורה עליונה)
A2: Raito מוכר B2B | B2B ₪10.50 מומלץ | עמלת מעיין 18% | כל הנתונים מצליבים הפניה לתחזית מכירות — שנה הנחות לעדכון
A4: סיכום רווח והפסד — שורת הכנסות B2B עליונה | כל הערכים ב-₪
B5: שמרני | F5: בסיס | J5: אופטימי
A6: סעיף | B6: H1-2026 (יול׳–דצמ׳) | C6: H1-2027 (ינו׳–יונ׳) | D6: H2-2027 (יול׳–דצמ׳) | E6: סה״כ 18 חודשים | F6: H1-2026 (יול׳–דצמ׳) | G6: H1-2027 (ינו׳–יונ׳) | H6: H2-2027 (יול׳–דצמ׳) | I6: סה״כ 18 חודשים | J6: H1-2026 (יול׳–דצמ׳) | K6: H1-2027 (ינו׳–יונ׳) | L6: H2-2027 (יול׳–דצמ׳) | M6: סה״כ 18 חודשים
A7: הכנסות B2B (חשבונית Raito) | B7: ='תחזית מכירות'!$E$25 | C7: ='תחזית מכירות'!$E$26 | D7: ='תחזית מכירות'!$E$27 | E7: ='תחזית מכירות'!$E$28 | F7: ='תחזית מכירות'!$E$51 | G7: ='תחזית מכירות'!$E$52 | H7: ='תחזית מכירות'!$E$53 | I7: ='תחזית מכירות'!$E$54 | J7: ='תחזית מכירות'!$E$77 | K7: ='תחזית מכירות'!$E$78 | L7: ='תחזית מכירות'!$E$79 | M7: ='תחזית מכירות'!$E$80
A8: – עמלת מעיין | B8: ='תחזית מכירות'!$F$25 | C8: ='תחזית מכירות'!$F$26 | D8: ='תחזית מכירות'!$F$27 | E8: ='תחזית מכירות'!$F$28 | F8: ='תחזית מכירות'!$F$51 | G8: ='תחזית מכירות'!$F$52 | H8: ='תחזית מכירות'!$F$53 | I8: ='תחזית מכירות'!$F$54 | J8: ='תחזית מכירות'!$F$77 | K8: ='תחזית מכירות'!$F$78 | L8: ='תחזית מכירות'!$F$79 | M8: ='תחזית מכירות'!$F$80
A9: ► הכנסות נטו ל-Raito | B9: ='תחזית מכירות'!$G$25 | C9: ='תחזית מכירות'!$G$26 | D9: ='תחזית מכירות'!$G$27 | E9: ='תחזית מכירות'!$G$28 | F9: ='תחזית מכירות'!$G$51 | G9: ='תחזית מכירות'!$G$52 | H9: ='תחזית מכירות'!$G$53 | I9: ='תחזית מכירות'!$G$54 | J9: ='תחזית מכירות'!$G$77 | K9: ='תחזית מכירות'!$G$78 | L9: ='תחזית מכירות'!$G$79 | M9: ='תחזית מכירות'!$G$80
A10: – עלות ייצור (עלות המכר) | B10: ='תחזית מכירות'!$H$25 | C10: ='תחזית מכירות'!$H$26 | D10: ='תחזית מכירות'!$H$27 | E10: ='תחזית מכירות'!$H$28 | F10: ='תחזית מכירות'!$H$51 | G10: ='תחזית מכירות'!$H$52 | H10: ='תחזית מכירות'!$H$53 | I10: ='תחזית מכירות'!$H$54 | J10: ='תחזית מכירות'!$H$77 | K10: ='תחזית מכירות'!$H$78 | L10: ='תחזית מכירות'!$H$79 | M10: ='תחזית מכירות'!$H$80
A11: ► רווח גולמי | B11: ='תחזית מכירות'!$I$25 | C11: ='תחזית מכירות'!$I$26 | D11: ='תחזית מכירות'!$I$27 | E11: ='תחזית מכירות'!$I$28 | F11: ='תחזית מכירות'!$I$51 | G11: ='תחזית מכירות'!$I$52 | H11: ='תחזית מכירות'!$I$53 | I11: ='תחזית מכירות'!$I$54 | J11: ='תחזית מכירות'!$I$77 | K11: ='תחזית מכירות'!$I$78 | L11: ='תחזית מכירות'!$I$79 | M11: ='תחזית מכירות'!$I$80
A12: שיעור רווח גולמי % | B12: =IFERROR('תחזית מכירות'!$I$25/'תחזית מכירות'!$E$25,0) | C12: =IFERROR('תחזית מכירות'!$I$26/'תחזית מכירות'!$E$26,0) | D12: =IFERROR('תחזית מכירות'!$I$27/'תחזית מכירות'!$E$27,0) | E12: =IFERROR('תחזית מכירות'!$I$28/'תחזית מכירות'!$E$28,0) | F12: =IFERROR('תחזית מכירות'!$I$51/'תחזית מכירות'!$E$51,0) | G12: =IFERROR('תחזית מכירות'!$I$52/'תחזית מכירות'!$E$52,0) | H12: =IFERROR('תחזית מכירות'!$I$53/'תחזית מכירות'!$E$53,0) | I12: =IFERROR('תחזית מכירות'!$I$54/'תחזית מכירות'!$E$54,0) | J12: =IFERROR('תחזית מכירות'!$I$77/'תחזית מכירות'!$E$77,0) | K12: =IFERROR('תחזית מכירות'!$I$78/'תחזית מכירות'!$E$78,0) | L12: =IFERROR('תחזית מכירות'!$I$79/'תחזית מכירות'!$E$79,0) | M12: =IFERROR('תחזית מכירות'!$I$80/'תחזית מכירות'!$E$80,0)
A13: יחידות שנמכרו | B13: ='תחזית מכירות'!$D$25 | C13: ='תחזית מכירות'!$D$26 | D13: ='תחזית מכירות'!$D$27 | E13: ='תחזית מכירות'!$D$28 | F13: ='תחזית מכירות'!$D$51 | G13: ='תחזית מכירות'!$D$52 | H13: ='תחזית מכירות'!$D$53 | I13: ='תחזית מכירות'!$D$54 | J13: ='תחזית מכירות'!$D$77 | K13: ='תחזית מכירות'!$D$78 | L13: ='תחזית מכירות'!$D$79 | M13: ='תחזית מכירות'!$D$80
A14: הכנסות B2C חודשיות (לעיון) | B14: ='תחזית מכירות'!$C$25 | C14: ='תחזית מכירות'!$C$26 | D14: ='תחזית מכירות'!$C$27 | E14: ='תחזית מכירות'!$C$28 | F14: ='תחזית מכירות'!$C$51 | G14: ='תחזית מכירות'!$C$52 | H14: ='תחזית מכירות'!$C$53 | I14: ='תחזית מכירות'!$C$54 | J14: ='תחזית מכירות'!$C$77 | K14: ='תחזית מכירות'!$C$78 | L14: ='תחזית מכירות'!$C$79 | M14: ='תחזית מכירות'!$C$80
A16: פירוט כלכלת יחידה (ליחידה — מהנחות, זהה בכל התקופות)
A17: מחיר B2B ליחידה | B17: =הנחות!$B$15 | C17: מחיר חשבונית B2B מומלץ — הנחות B15
A18: – עמלת מעיין ליחידה | B18: =הנחות!$B$15*הנחות!$B$14 | C18: B2B × שיעור עמלה
A19: ► הכנסות נטו ליחידה (ל-Raito) | B19: =הנחות!$B$15*(1-הנחות!$B$14) | C19: B2B × (1 − עמלה)
A20: – עלות ייצור ליחידה (150 גרם) | B20: =הנחות!$B$7 | C20: ₪3.70 × 1.5 = ₪5.55 — הנחות B7
A21: ► רווח גולמי ליחידה | B21: =הנחות!$B$15*(1-הנחות!$B$14)-הנחות!$B$7 | C21: הכנסות נטו פחות עלות ייצור
A22: שיעור רווח גולמי % (ליחידה) | B22: =IFERROR((הנחות!$B$15*(1-הנחות!$B$14)-הנחות!$B$7)/הנחות!$B$15,0) | C22: GP ÷ מחיר B2B
