Workbook

Sheet סיכום ניהולי
A1: AHLAN — השוואת 3 פורמטים | סיכום ניהולי
A2: תקופה: ספטמבר 2026 → אוגוסט 2028 · 24 חודשים · עלות ייצור ₪3.87/100g · תקציב שיווק ₪500K–₪1M, 50/50 Raito/Ma Kashur
A4: החלטות מהפגישה עם CEO + Ma Kashur
A5: בחירת פורמט | B5: בוחנים 3 פורמטים במקביל כל אחד כמקרה עצמאי: 150g (קיים), 3×100g (מארז חדש), 100g (יחידה חדשה)
A6: עלות ייצור | B6: ₪3.87 ל-100 גרם — מתכלל על כל הפורמטים (150g=₪5.805, 3×100g=₪11.61, 100g=₪3.87)
A7: לוח זמנים | B7: ספטמבר 2026 → אוגוסט 2028 — 24 חודשים, שלושה שלבים: השקה (M1-6), הרחבה (M7-18), בגרות (M19-24)
A8: שיווק | B8: תקציב כולל ₪500K–₪1M — 50/50 Raito / Ma Kashur. אסטרטגיה: אורגני דרך Ma Kashur (משפיענים, תוכן), לא מס מדיה
A9: תמחור | B9: נגזר מ-benchmarks של CHP (94 רשתות) ו-Store Next (פאנל קמעונאות מאורגנת)
A10: מדדי הצלחה | B10: לכל פורמט מוגדר יעד נתח שוק מגזרי ייחודי לפי דינמיקת הסגמנט
A12: תוצאות כלכליות להשוואה — שנה 1 (ספט 2026 → אוג 2027)
A13: פורמט | B13: מחיר B2B | C13: מחיר מדף (פרטי) | D13: הכנסות B2B (Raito) | E13: יחידות | F13: רווח גולמי | G13: % מרווח גולמי | H13: EBITDA (אחרי שיווק)
A14: 150 גרם (קיים) | B14: =הנחות!$B$41 -> 8.9 | C14: =הנחות!$B$41/(1-הנחות!$B$15)*(1+הנחות!$B$13) -> 13.1275 | D14: ='תחזית 150 גרם'!F31 -> 17807910 | E14: ='תחזית 150 גרם'!E31 -> 2000888.7 | F14: ='תחזית 150 גרם'!I31 -> 2987326.9 | G14: =IFERROR(F14/D14,0) -> 0.16775281 | H14: ='רווח והפסד'!D17 -> 2762326.9
A15: 3×100 גרם (חדש) | B15: =הנחות!$B$46 -> 19.5 | C15: =הנחות!$B$46/(1-הנחות!$B$15)*(1+הנחות!$B$13) -> 28.7625 | D15: ='תחזית 3x100 גרם'!F31 -> 7123163.8 | E15: ='תחזית 3x100 גרם'!E31 -> 365290.45 | F15: ='תחזית 3x100 גרם'!I31 -> 1599972.2 | G15: =IFERROR(F15/D15,0) -> 0.22461538 | H15: ='רווח והפסד'!E17 -> 1374972.2
A16: 100 גרם (חדש) | B16: =הנחות!$B$51 -> 6.5 | C16: =הנחות!$B$51/(1-הנחות!$B$15)*(1+הנחות!$B$13) -> 9.5875 | D16: ='תחזית 100 גרם'!F31 -> 10684746 | E16: ='תחזית 100 גרם'!E31 -> 1643807 | F16: ='תחזית 100 גרם'!I31 -> 2399958.3 | G16: =IFERROR(F16/D16,0) -> 0.22461538 | H16: ='רווח והפסד'!F17 -> 2174958.3
A18: תוצאות כלכליות להשוואה — שנה 2 (ספט 2027 → אוג 2028)
A19: פורמט | B19: הכנסות B2B שנה 2 | C19: יחידות שנה 2 | D19: צמיחה מול שנה 1 | E19: רווח גולמי שנה 2 | F19: EBITDA שנה 2 | G19: סה״כ הכנסות 2 שנים | H19: סה״כ EBITDA 2 שנים
A20: 150 גרם | B20: ='תחזית 150 גרם'!F56 -> 34463277 | C20: ='תחזית 150 גרם'!E56 -> 3872278.3 | D20: =IFERROR(B20/D14-1,0) -> 0.93527919 | E20: ='תחזית 150 גרם'!I56 -> 5781311.5 | F20: ='רווח והפסד'!D18 -> 5631311.5 | G20: =D14+B20 -> 52271186 | H20: ='רווח והפסד'!D17+'רווח והפסד'!D18 -> 8393638.4
A21: 3×100 גרם | B21: ='תחזית 3x100 גרם'!F56 -> 15254237 | C21: ='תחזית 3x100 גרם'!E56 -> 782268.58 | D21: =IFERROR(B21/D15-1,0) -> 1.1414975 | E21: ='תחזית 3x100 גרם'!I56 -> 3426336.4 | F21: ='רווח והפסד'!E18 -> 3276336.4 | G21: =D15+B21 -> 22377401 | H21: ='רווח והפסד'!E17+'רווח והפסד'!E18 -> 4651308.6
A22: 100 גרם | B22: ='תחזית 100 גרם'!F56 -> 20677966 | C22: ='תחזית 100 גרם'!E56 -> 3181225.6 | D22: =IFERROR(B22/D16-1,0) -> 0.93527919 | E22: ='תחזית 100 גרם'!I56 -> 4644589.3 | F22: ='רווח והפסד'!F18 -> 4494589.3 | G22: =D16+B22 -> 31362712 | H22: ='רווח והפסד'!F17+'רווח והפסד'!F18 -> 6669547.6
A24: המלצה ניהולית
A25: המלצתנו: להשיק את ה-150g כפורמט הדגל (white space לפי CHP עם 8/94 רשתות בלבד, וצמיחה של +113% ב-Store Next). להוסיף את ה-3×100g במקביל כמארז משפחה/ערך (רוכב על הטרנד הגדל של מארזי 98×3 ו-4×115g ב-Store Next). לדחות את ה-100g לשלב 2 — הסגמנט הגדול אבל בלחץ תחרותי מ-Elite 70% נוכחות רשתות ובמגמת ירידה. תקציב שיווק ₪750K (נקודת האמצע) מאוזן בין היקף לבין יכולת Ma Kashur לייצר נוכחות אורגנית דרך משפיענים ותוכן.

Sheet הנחות
A1: הנחות המודל — 3 פורמטים | כל התאים הכחולים ניתנים לעריכה
A2: כל חישוב בגיליונות האחרים קושר לתאים כאן · שינוי ערך = חישוב מחדש של כל המודל
A4: A. עלויות ייצור (₪3.87 ל-100 גרם — מאושר)
A5: פריט | B5: ערך | C5: יחידה | D5: הערות
A6: עלות ייצור ל-100 גרם (בסיס) | B6: 3.87 | C6: ₪/100g | D6: החלטה מאושרת — החליף ₪3.70 הקודם
A7: עלות ייצור ל-150 גרם | B7: =הנחות!$B$6*1.5 -> 5.805 | C7: ₪/150g | D7: נוסחה: עלות 100g × 1.5 = ₪5.805
A8: עלות ייצור למארז 3×100 גרם | B8: =הנחות!$B$6*3 -> 11.61 | C8: ₪/מארז | D8: נוסחה: עלות 100g × 3 = ₪11.61 (ללא עלות אריזת מארז נוספת)
A9: עלות ייצור ל-100 גרם (יחידה) | B9: =הנחות!$B$6 -> 3.87 | C9: ₪/יחידה | D9: זהה לעלות הבסיס
A11: B. תמחור וערוצים
A12: פריט | B12: ערך | C12: יחידה | D12: הערות
A13: מע״מ בישראל | B13: 0.18 | C13: % | D13: תקן 2026
A14: מרווח קמעונאי — רשתות מאורגנות (שופרסל, יינות ביתן, רמי לוי) | B14: 0.3 | C14: % | D14: מרווח ברשתות מאורגנות
A15: מרווח קמעונאי — שוק פרטי / ערוץ מעיין | B15: 0.2 | C15: % | D15: חנויות עצמאיות, מינימרקטים, שוק
A16: עמלת הפצה מעיין | B16: 0.18 | C16: % | D16: טווח 15–25% — 18% בסיס
A19: C. גודל שוק | מקור: CHP 03/2026 + Store Next + דוחות תעשייה ישראליים
A20: פריט | B20: ערך | C20: יחידה | D20: הערות
A21: שוק קפה שחור כולל — ישראל (B2C שנתי) | B21: 830000000 | C21: ₪/year | D21: מקור: כלכליסט 03/2025 — שטראוס/Elite ≥80% נתח
A22: סגמנט קפה טורקי — ישראל (B2C שנתי) | B22: 400000000 | C22: ₪/year | D22: מקור: מחקר תעשייה — כ-40% משוק הקפה; במגזר הערבי 76% העדפה
A23: מכפיל פאנל Store Next — נמוך | B23: 15 | C23: × | D23: Store Next מכסה רק רשתות מאורגנות; שוק פרטי × 15
A24: מכפיל פאנל Store Next — גבוה | B24: 20 | C24: × | D24: גבול עליון — אימות
A25: D. מקדמי תרחיש (חלים על נתח השוק בכל הפורמטים)
A26: תרחיש | B26: מקדם | C26: נתח שיא | D26: תיאור
A27: שמרני | B27: 0.7 | C27: 70% מיעד | D27: שיווק מתחת לציפיות; עדיין חזק ללא סלבריטי
A28: בסיס | B28: 1 | C28: 100% מיעד | D28: לפי תוכנית; Ma Kashur מספק כמתוכנן
A29: אופטימי | B29: 1.3 | C29: 130% מיעד | D29: אימוץ ויראלי; תוכן Ma Kashur פורץ דרך
A30: E. תקציב שיווק (משותף ל-3 הפורמטים)
A31: פריט | B31: ערך | C31: יחידה | D31: הערות
A32: סה״כ תקציב שיווק (24 חודשים) | B32: 750000 | C32: ₪ | D32: בסיס — טווח ₪500K–₪1M. שנה את הערך לבדיקת רגישות
A33: חלק Raito | B33: 0.5 | C33: % | D33: Raito מממנת 50% מהתקציב
A34: חלק Ma Kashur | B34: 0.5 | C34: % | D34: Ma Kashur מממנת 50% מהתקציב (שותפות שוות)
A35: תרומת Raito ב-₪ | B35: =הנחות!$B$32*הנחות!$B$33 -> 375000 | C35: ₪ | D35: נוסחה: סה״כ × חלק Raito
A36: תרומת Ma Kashur ב-₪ | B36: =הנחות!$B$32*הנחות!$B$34 -> 375000 | C36: ₪ | D36: נוסחה: סה״כ × חלק Ma Kashur
A38: F. פרמטרים ספציפיים לפורמט — מחיר B2B ויעדי נתח שוק
A39: פרמטר | B39: ערך | C39: יחידה | D39: הערות / מקור benchmark
A40: פורמט 150g — קיים | B40: Benchmark CHP: Elite 150g ₪13.14 avg | 8/94 רשתות | White space. Store Next: +113% הכנסות 2024→2025, +52% שינוי נתח YTD
A41: מחיר B2B ל-150g | B41: 8.9 | C41: ₪/unit | D41: יעד: מחיר מדף ~₪12.90 בשוק פרטי (20% ret), זול מ-Elite ₪13.14
A42: יעד נתח שוק 150g — M12 (בסיס) | B42: 0.1 | C42: % | D42: חודש 12 (אוג 2027) — אגרסיבי בגלל white space בסגמנט
A43: יעד נתח שוק 150g — M24 (בסיס) | B43: 0.15 | C43: % | D43: חודש 24 (אוג 2028) — בגרות
A45: פורמט 3×100g — חדש | B45: Benchmark CHP: Elite 3×85g ₪24.46 avg | 51/94 רשתות (54%). Store Next: 98×3 + 4×115g growing rapidly (new formats); 3×85g declining
A46: מחיר B2B למארז 3×100g | B46: 19.5 | C46: ₪/מארז | D46: יעד: מחיר מדף ~₪27.90 במארז (20% ret) — ~ערך של 100g ב-₪9.30 — משמעותית זול מ-Elite 100g ₪11.53
...

Sheet מודיעין שוק
A1: מודיעין שוק | CHP (94 רשתות, 03/2026) + Store Next (פאנל קמעונאות מאורגנת)
A2: Benchmarks ממקורות אובייקטיביים ישראליים · מהווים את הבסיס להערכת ה-benchmarks ויעדי הנתח
A4: A. CHP — השוואת מחירים בין 94 רשתות | SKUs של Elite
A5: SKU | B5: מחיר ממוצע (₪) | C5: חציון (₪) | D5: טווח מחירים | E5: רשתות נוכחות | F5: % רשתות | G5: עלות / 100g
A6: Elite 100g (דומיננטי) | B6: 11.53 | C6: 11.9 | D6: ₪5.90 – ₪14.90 | E6: 66/94 | F6: 0.70212766 | G6: 11.53
A7: Elite 150g (white space) | B7: 13.14 | C7: 12.9 | D7: ₪12.10 – ₪14.90 | E7: 8/94 | F7: 0.085106383 | G7: 8.76
A8: Elite 200g | B8: 19.25 | C8: 19 | D8: ₪14.90 – ₪23.50 | E8: 72/94 | F8: 0.76595745 | G8: 9.63
A9: Elite 85g | B9: 9.12 | C9: 9.1 | D9: ₪8.20 – ₪9.90 | E9: 6/94 | F9: 0.063829787 | G9: 10.73
A10: Elite 3×85g (multi) | B10: 24.46 | C10: 25.4 | D10: ₪19.90 – ₪32.90 | E10: 51/94 | F10: 0.54255319 | G10: 9.59
A11: Elite 7×24g on-the-go | B11: 20.83 | C11: 21.9 | D11: ₪14.90 – ₪27.90 | E11: 75/94 | F11: 0.79787234 | G11: 12.4
A13: B. Store Next — פאנל קמעונאות מאורגנת | מכירות ונתחי שוק
A14: SKU | B14: מכירות 2024 (K) | C14: מכירות 2025 (K) | D14: מגמה | E14: נתח 2024 | F14: נתח 2025 | G14: שינוי נתח YTD
A15: Elite 100g | B15: 2547.96 | C15: 2172.19 | D15: יציב-יורד | E15: 0.078 | F15: 0.071 | G15: -0.037
A16: Elite 150g (שקית) | B16: 526.19 | C16: 1124.84 | D16: +113% צמיחה | E16: 0.022 | F16: 0.045 | G16: 0.524
A17: Elite 200g | B17: 4649.19 | C17: 3875.63 | D17: יורד | E17: 0.242 | F17: 0.204 | G17: 0.042
A18: Elite 85g | B18: 1380.69 | C18: 1106.28 | D18: יורד | E18: — | F18: — | G18: —
A19: Elite 168g (on-the-go) | B19: 526.38 | C19: 660.33 | D19: צומח | E19: — | F19: — | G19: —
A20: Elite 3×85g (multi) | B20: 1119.26 | C20: 945.32 | D20: יורד | E20: 0.07 | F20: 0.063 | G20: —
A21: Elite 4×100g (multi) | B21: — | C21: — | D21: — | E21: 0.08 | F21: 0.054 | G21: -0.088
A22: Elite 3×125g (multi) | B22: — | C22: — | D22: — | E22: 0.077 | F22: 0.076 | G22: 0.217
A23: Elite 98×3 גדל (multi) | B23: — | C23: 0.08 | D23: חדש — מתפוצץ | E23: — | F23: 0 | G23: —
A24: Elite 4×115g (חדש) | B24: — | C24: — | D24: חדש | E24: — | F24: — | G24: —
A26: C. מקורות שוק ישראליים — נתוני תעשייה
A27: שוק קפה כולל ישראל | B27: ~₪1.5B שנתי | C27: כלכליסט (03/2025), שטראוס מסכמת 2024
A28: שוק קפה שחור (רטיל) | B28: ~₪830M שנתי | C28: כלכליסט — העלאות מחירים הובילו לצמיחת 4.7% ב-2024
A29: סגמנט קפה טורקי | B29: ~₪400M שנתי | C29: מחקר — ~40% משוק הקפה השחור
A30: העדפת קפה טורקי במגזר ערבי | B30: 76% | C30: מחקר שוק — קפה טורקי = המוצר המוביל
A31: צריכת קפה בישראל | B31: 6.57 kg לנפש (2021) | C31: מקור: נתונים כלל-תעשייתיים
A32: נתח Elite/שטראוס בקפה שחור | B32: 80%+ | C32: כלכליסט — נתח שטראוס בסגמנט
A33: פורמט 100g = הפופולרי | B33: ~80% משקי בית | C33: סקר פנימי של Elite / ynet
A34: השקה תחרות לטורקי | B34: Asala של Elite | C34: ice.co.il — קמפיין ייעודי למגזר הערבי $1M
A36: D. מסקנות מהבנצ'מרקים — השפעה על יעדי הפורמטים
A37: 150g — White Space | B37: Elite ב-8/94 רשתות בלבד (8.5%). Store Next: +113% צמיחת הכנסות ו-+52% שינוי נתח YTD. הפורמט הכי חלש בהפצה כיום, אבל בצמיחה המהירה ביותר — עבור AHLAN הזדמנות לבעלות על סגמנט צומח ללא תחרות מבוססת
A38: 3×100g — מארז בצמיחה | B38: Elite 3×85g ב-51/94 רשתות (54%). Store Next: מארזי 3×85g ו-4×100g בירידה, אבל מארזי 98×3 (כ-3×100g) ו-4×115g חדשים ובצמיחה מתפוצצת. התזמון מושלם להשיק מארז 3×100g — הצרכן כבר מכיר את המבנה, התמחור לפר-100g מייצר ערך
A39: 100g — דומיננטי אבל תחרותי | B39: Elite ב-66/94 רשתות (70%) — הכי רחב. Store Next: נתח יציב ~7%, אבל בירידה של -3.7% YTD. הסגמנט הגדול ביותר אבל בלחץ תחרותי עז מ-Elite — חדירה אפשרית אבל דורשת יתרון מחיר או ערך משמעותי

Sheet כלכלת יחידה
A1: כלכלת יחידה — השוואת 3 פורמטים ביחידה אחת
A2: מחיר B2B ← עלות ייצור ← מרווח גולמי | כל השדות מקושרים להנחות — שנה שם לחישוב מחדש
A4: A. שרשרת תמחור — ערוץ שוק פרטי (מעיין) 20% מרווח קמעונאי
A5: סעיף | B5: 150g (יחידה) | C5: 3×100g (מארז) | D5: 100g (יחידה) | E5: הערות
A6: מחיר B2B (חשבונית Raito) | B6: =הנחות!$B$41 -> 8.9 | C6: =הנחות!$B$46 -> 19.5 | D6: =הנחות!$B$51 -> 6.5 | E6: קלט מגיליון ההנחות
A7: עמלת מפיץ (מעיין) | B7: =הנחות!$B$41*הנחות!$B$16 -> 1.602 | C7: =הנחות!$B$46*הנחות!$B$16 -> 3.51 | D7: =הנחות!$B$51*הנחות!$B$16 -> 1.17 | E7: B2B × 18% עמלה
A8: הכנסות נטו ל-Raito | B8: =הנחות!$B$41*(1-הנחות!$B$16) -> 7.298 | C8: =הנחות!$B$46*(1-הנחות!$B$16) -> 15.99 | D8: =הנחות!$B$51*(1-הנחות!$B$16) -> 5.33 | E8: B2B − עמלת מפיץ
A9: עלות ייצור (COGS) | B9: =הנחות!$B$7 -> 5.805 | C9: =הנחות!$B$8 -> 11.61 | D9: =הנחות!$B$9 -> 3.87 | E9: ישירות מההנחות — ₪3.87/100g
A10: רווח גולמי ליחידה | B10: =הנחות!$B$41*(1-הנחות!$B$16)-הנחות!$B$7 -> 1.493 | C10: =הנחות!$B$46*(1-הנחות!$B$16)-הנחות!$B$8 -> 4.38 | D10: =הנחות!$B$51*(1-הנחות!$B$16)-הנחות!$B$9 -> 1.46 | E10: הכנסות נטו − עלות ייצור
A11: מרווח גולמי % (GP ÷ B2B) | B11: =(הנחות!$B$41*(1-הנחות!$B$16)-הנחות!$B$7)/הנחות!$B$41 -> 0.16775281 | C11: =(הנחות!$B$46*(1-הנחות!$B$16)-הנחות!$B$8)/הנחות!$B$46 -> 0.22461538 | D11: =(הנחות!$B$51*(1-הנחות!$B$16)-הנחות!$B$9)/הנחות!$B$51 -> 0.22461538 | E11: GP ÷ מחיר B2B
A13: B. שרשרת מחיר → מדף B2C (ערוץ שוק פרטי 20% ret)
A14: מחיר מדף B2C — שוק פרטי (20% ret + 18% מע״מ) | B14: =הנחות!$B$41/(1-הנחות!$B$15)*(1+הנחות!$B$13) -> 13.1275 | C14: =הנחות!$B$46/(1-הנחות!$B$15)*(1+הנחות!$B$13) -> 28.7625 | D14: =הנחות!$B$51/(1-הנחות!$B$15)*(1+הנחות!$B$13) -> 9.5875 | E14: B2B ÷ (1-20%) × (1+18%)
A15: מחיר מדף ל-100g (נורמלי) | B15: =(הנחות!$B$41/(1-הנחות!$B$15)*(1+הנחות!$B$13))/1.5 -> 8.7516667 | C15: =(הנחות!$B$46/(1-הנחות!$B$15)*(1+הנחות!$B$13))/3 -> 9.5875 | D15: =הנחות!$B$51/(1-הנחות!$B$15)*(1+הנחות!$B$13) -> 9.5875 | E15: מדף ÷ גרם-100 שווה-ערך
A17: C. השוואה לתחרות — Elite Benchmarks מ-CHP
A18: מדד | B18: 150g | C18: 3×100g | D18: 100g | E18: הערות
A19: Elite מחיר מדף ממוצע (CHP) | B19: 13.14 | C19: 28.77 | D19: 11.53 | E19: CHP 03/2026; 3×100g scaled from 3×85g
A20: AHLAN vs Elite (הנחה) | B20: =(הנחות!$B$41/(1-הנחות!$B$15)*(1+הנחות!$B$13))/B19-1 -> -0.00095129376 | C20: =(הנחות!$B$46/(1-הנחות!$B$15)*(1+הנחות!$B$13))/C19-1 -> -0.00026068822 | D20: =(הנחות!$B$51/(1-הנחות!$B$15)*(1+הנחות!$B$13))/D19-1 -> -0.16847355 | E20: % הפרש של AHLAN מ-Elite (שלילי = זול יותר)
A22: D. רגישות מחיר B2B — חישוב רווח גולמי ליחידה בסימולציות
A23: פורמט 150g — רגישות למחיר B2B | B23: רווח גולמי ליחידה בסימולציות מחיר שונות (COGS=₪5.81, ואיחיל)
A24: מחיר B2B | B24: הכנסות נטו | C24: רווח גולמי | D24: GM% | E24: מדף B2C
A25: 7.5 | B25: =A25*(1-הנחות!$B$16) -> 6.15 | C25: =A25*(1-הנחות!$B$16)-הנחות!$B$7 -> 0.345 | D25: =C25/A25 -> 0.046 | E25: =A25/(1-הנחות!$B$15)*(1+הנחות!$B$13) -> 11.0625
A26: 8 | B26: =A26*(1-הנחות!$B$16) -> 6.56 | C26: =A26*(1-הנחות!$B$16)-הנחות!$B$7 -> 0.755 | D26: =C26/A26 -> 0.094375 | E26: =A26/(1-הנחות!$B$15)*(1+הנחות!$B$13) -> 11.8
A27: 8.5 | B27: =A27*(1-הנחות!$B$16) -> 6.97 | C27: =A27*(1-הנחות!$B$16)-הנחות!$B$7 -> 1.165 | D27: =C27/A27 -> 0.13705882 | E27: =A27/(1-הנחות!$B$15)*(1+הנחות!$B$13) -> 12.5375
A28: 8.9 | B28: =A28*(1-הנחות!$B$16) -> 7.298 | C28: =A28*(1-הנחות!$B$16)-הנחות!$B$7 -> 1.493 | D28: =C28/A28 -> 0.16775281 | E28: =A28/(1-הנחות!$B$15)*(1+הנחות!$B$13) -> 13.1275
A29: 9.5 | B29: =A29*(1-הנחות!$B$16) -> 7.79 | C29: =A29*(1-הנחות!$B$16)-הנחות!$B$7 -> 1.985 | D29: =C29/A29 -> 0.20894737 | E29: =A29/(1-הנחות!$B$15)*(1+הנחות!$B$13) -> 14.0125
A30: 10 | B30: =A30*(1-הנחות!$B$16) -> 8.2 | C30: =A30*(1-הנחות!$B$16)-הנחות!$B$7 -> 2.395 | D30: =C30/A30 -> 0.2395 | E30: =A30/(1-הנחות!$B$15)*(1+הנחות!$B$13) -> 14.75
A31: 10.5 | B31: =A31*(1-הנחות!$B$16) -> 8.61 | C31: =A31*(1-הנחות!$B$16)-הנחות!$B$7 -> 2.805 | D31: =C31/A31 -> 0.26714286 | E31: =A31/(1-הנחות!$B$15)*(1+הנחות!$B$13) -> 15.4875
A33: פורמט 3×100g — רגישות למחיר B2B | B33: רווח גולמי ליחידה בסימולציות מחיר שונות (COGS=₪11.61)
A34: מחיר B2B | B34: הכנסות נטו | C34: רווח גולמי | D34: GM% | E34: מדף B2C
A35: 16.5 | B35: =A35*(1-הנחות!$B$16) -> 13.53 | C35: =A35*(1-הנחות!$B$16)-הנחות!$B$8 -> 1.92 | D35: =C35/A35 -> 0.11636364 | E35: =A35/(1-הנחות!$B$15)*(1+הנחות!$B$13) -> 24.3375
A36: 17.5 | B36: =A36*(1-הנחות!$B$16) -> 14.35 | C36: =A36*(1-הנחות!$B$16)-הנחות!$B$8 -> 2.74 | D36: =C36/A36 -> 0.15657143 | E36: =A36/(1-הנחות!$B$15)*(1+הנחות!$B$13) -> 25.8125
A37: 18.5 | B37: =A37*(1-הנחות!$B$16) -> 15.17 | C37: =A37*(1-הנחות!$B$16)-הנחות!$B$8 -> 3.56 | D37: =C37/A37 -> 0.19243243 | E37: =A37/(1-הנחות!$B$15)*(1+הנחות!$B$13) -> 27.2875
A38: 19.5 | B38: =A38*(1-הנחות!$B$16) -> 15.99 | C38: =A38*(1-הנחות!$B$16)-הנחות!$B$8 -> 4.38 | D38: =C38/A38 -> 0.22461538 | E38: =A38/(1-הנחות!$B$15)*(1+הנחות!$B$13) -> 28.7625
A39: 20.5 | B39: =A39*(1-הנחות!$B$16) -> 16.81 | C39: =A39*(1-הנחות!$B$16)-הנחות!$B$8 -> 5.2 | D39: =C39/A39 -> 0.25365854 | E39: =A39/(1-הנחות!$B$15)*(1+הנחות!$B$13) -> 30.2375
A40: 21.5 | B40: =A40*(1-הנחות!$B$16) -> 17.63 | C40: =A40*(1-הנחות!$B$16)-הנחות!$B$8 -> 6.02 | D40: =C40/A40 -> 0.28 | E40: =A40/(1-הנחות!$B$15)*(1+הנחות!$B$13) -> 31.7125
A41: 22.5 | B41: =A41*(1-הנחות!$B$16) -> 18.45 | C41: =A41*(1-הנחות!$B$16)-הנחות!$B$8 -> 6.84 | D41: =C41/A41 -> 0.304 | E41: =A41/(1-הנחות!$B$15)*(1+הנחות!$B$13) -> 33.1875
A43: פורמט 100g — רגישות למחיר B2B | B43: רווח גולמי ליחידה בסימולציות מחיר שונות (COGS=₪3.87)
A44: מחיר B2B | B44: הכנסות נטו | C44: רווח גולמי | D44: GM% | E44: מדף B2C
A45: 5.5 | B45: =A45*(1-הנחות!$B$16) -> 4.51 | C45: =A45*(1-הנחות!$B$16)-הנחות!$B$9 -> 0.64 | D45: =C45/A45 -> 0.11636364 | E45: =A45/(1-הנחות!$B$15)*(1+הנחות!$B$13) -> 8.1125
A46: 6 | B46: =A46*(1-הנחות!$B$16) -> 4.92 | C46: =A46*(1-הנחות!$B$16)-הנחות!$B$9 -> 1.05 | D46: =C46/A46 -> 0.175 | E46: =A46/(1-הנחות!$B$15)*(1+הנחות!$B$13) -> 8.85
...

Sheet תחזית 150 גרם
A1: תחזית מכירות חודשית — פורמט 150g · 24 חודשים
A2: ספט 2026 → אוג 2028 · B2B ₪8.9 (הנחות) · גודל שוק ₪400M טורקי (מ-תא C22)
A4: A. שלבי השקה (Phases) — הגדרת הנחות הרמפ
A5: שלב | B5: חודשים | C5: נתח יעד | D5: פעילות שיווק | E5: הערות
A6: השקה (Launch) | B6: M1-M6 | C6: 0-70% מ-M12 | D6: Ma Kashur content blitz, משפיענים, PR, דגימות | E6: בניית מודעות למותג, חשיפה של המוצר הערבי-ישראלי המקומי
A7: הרחבה (Expand) | B7: M7-M18 | C7: 70% → M24 target | D7: המשך תוכן, שיתופי פעולה, מבצעים עונתיים | E7: מיקוד על הרחבת הפצה לרשתות מאורגנות + צמיחה בשוק פרטי
A8: בגרות (Mature) | B8: M19-M24 | C8: יעד M24 מושג | D8: תחזוקה, מוצרי-המשך (flavors, packaging) | E8: שמירה על נתח, אופטימיזציה של עלויות ומרווחים
A10: B. תחזית חודשית — שנה 1 (ספט 2026 → אוג 2027) · פורמט 150g
A11: חודש | B11: M# | C11: שלב | D11: נתח יעד % | E11: יחידות | F11: הכנסות B2B | G11: עמלת מפיץ | H11: נטו ל-Raito | I11: רווח גולמי | J11: GM %
A12: ספט 2026 | B12: 1 | C12: השקה | D12: =0.08*הנחות!$B$42 -> 0.008 | E12: =(הנחות!$B$22/12)*D12/(הנחות!$B$41/(1-הנחות!$B$15)*(1+הנחות!$B$13)) -> 20313.591 | F12: =E12*הנחות!$B$41 -> 180790.96 | G12: =F12*הנחות!$B$16 -> 32542.373 | H12: =F12-G12 -> 148248.59 | I12: =H12-E12*הנחות!$B$7 -> 30328.191 | J12: =IFERROR(I12/F12,0) -> 0.16775281
A13: אוק 2026 | B13: 2 | C13: השקה | D13: =0.18*הנחות!$B$42 -> 0.018 | E13: =(הנחות!$B$22/12)*D13/(הנחות!$B$41/(1-הנחות!$B$15)*(1+הנחות!$B$13)) -> 45705.58 | F13: =E13*הנחות!$B$41 -> 406779.66 | G13: =F13*הנחות!$B$16 -> 73220.339 | H13: =F13-G13 -> 333559.32 | I13: =H13-E13*הנחות!$B$7 -> 68238.431 | J13: =IFERROR(I13/F13,0) -> 0.16775281
A14: נוב 2026 | B14: 3 | C14: השקה | D14: =0.3*הנחות!$B$42 -> 0.03 | E14: =(הנחות!$B$22/12)*D14/(הנחות!$B$41/(1-הנחות!$B$15)*(1+הנחות!$B$13)) -> 76175.966 | F14: =E14*הנחות!$B$41 -> 677966.1 | G14: =F14*הנחות!$B$16 -> 122033.9 | H14: =F14-G14 -> 555932.2 | I14: =H14-E14*הנחות!$B$7 -> 113730.72 | J14: =IFERROR(I14/F14,0) -> 0.16775281
A15: דצמ 2026 | B15: 4 | C15: השקה | D15: =0.45*הנחות!$B$42 -> 0.045 | E15: =(הנחות!$B$22/12)*D15/(הנחות!$B$41/(1-הנחות!$B$15)*(1+הנחות!$B$13)) -> 114263.95 | F15: =E15*הנחות!$B$41 -> 1016949.2 | G15: =F15*הנחות!$B$16 -> 183050.85 | H15: =F15-G15 -> 833898.31 | I15: =H15-E15*הנחות!$B$7 -> 170596.08 | J15: =IFERROR(I15/F15,0) -> 0.16775281
A16: ינו 2027 | B16: 5 | C16: השקה | D16: =0.6*הנחות!$B$42 -> 0.06 | E16: =(הנחות!$B$22/12)*D16/(הנחות!$B$41/(1-הנחות!$B$15)*(1+הנחות!$B$13)) -> 152351.93 | F16: =E16*הנחות!$B$41 -> 1355932.2 | G16: =F16*הנחות!$B$16 -> 244067.8 | H16: =F16-G16 -> 1111864.4 | I16: =H16-E16*הנחות!$B$7 -> 227461.44 | J16: =IFERROR(I16/F16,0) -> 0.16775281
A17: פבר 2027 | B17: 6 | C17: השקה | D17: =0.72*הנחות!$B$42 -> 0.072 | E17: =(הנחות!$B$22/12)*D17/(הנחות!$B$41/(1-הנחות!$B$15)*(1+הנחות!$B$13)) -> 182822.32 | F17: =E17*הנחות!$B$41 -> 1627118.6 | G17: =F17*הנחות!$B$16 -> 292881.36 | H17: =F17-G17 -> 1334237.3 | I17: =H17-E17*הנחות!$B$7 -> 272953.72 | J17: =IFERROR(I17/F17,0) -> 0.16775281
A18: מרץ 2027 | B18: 7 | C18: הרחבה | D18: =0.82*הנחות!$B$42 -> 0.082 | E18: =(הנחות!$B$22/12)*D18/(הנחות!$B$41/(1-הנחות!$B$15)*(1+הנחות!$B$13)) -> 208214.31 | F18: =E18*הנחות!$B$41 -> 1853107.3 | G18: =F18*הנחות!$B$16 -> 333559.32 | H18: =F18-G18 -> 1519548 | I18: =H18-E18*הנחות!$B$7 -> 310863.96 | J18: =IFERROR(I18/F18,0) -> 0.16775281
A19: אפר 2027 | B19: 8 | C19: הרחבה | D19: =0.88*הנחות!$B$42 -> 0.088 | E19: =(הנחות!$B$22/12)*D19/(הנחות!$B$41/(1-הנחות!$B$15)*(1+הנחות!$B$13)) -> 223449.5 | F19: =E19*הנחות!$B$41 -> 1988700.6 | G19: =F19*הנחות!$B$16 -> 357966.1 | H19: =F19-G19 -> 1630734.5 | I19: =H19-E19*הנחות!$B$7 -> 333610.11 | J19: =IFERROR(I19/F19,0) -> 0.16775281
A20: מאי 2027 | B20: 9 | C20: הרחבה | D20: =0.92*הנחות!$B$42 -> 0.092 | E20: =(הנחות!$B$22/12)*D20/(הנחות!$B$41/(1-הנחות!$B$15)*(1+הנחות!$B$13)) -> 233606.3 | F20: =E20*הנחות!$B$41 -> 2079096 | G20: =F20*הנחות!$B$16 -> 374237.29 | H20: =F20-G20 -> 1704858.8 | I20: =H20-E20*הנחות!$B$7 -> 348774.2 | J20: =IFERROR(I20/F20,0) -> 0.16775281
A21: יונ 2027 | B21: 10 | C21: הרחבה | D21: =0.95*הנחות!$B$42 -> 0.095 | E21: =(הנחות!$B$22/12)*D21/(הנחות!$B$41/(1-הנחות!$B$15)*(1+הנחות!$B$13)) -> 241223.89 | F21: =E21*הנחות!$B$41 -> 2146892.7 | G21: =F21*הנחות!$B$16 -> 386440.68 | H21: =F21-G21 -> 1760452 | I21: =H21-E21*הנחות!$B$7 -> 360147.27 | J21: =IFERROR(I21/F21,0) -> 0.16775281
A22: יול 2027 | B22: 11 | C22: הרחבה | D22: =0.98*הנחות!$B$42 -> 0.098 | E22: =(הנחות!$B$22/12)*D22/(הנחות!$B$41/(1-הנחות!$B$15)*(1+הנחות!$B$13)) -> 248841.49 | F22: =E22*הנחות!$B$41 -> 2214689.3 | G22: =F22*הנחות!$B$16 -> 398644.07 | H22: =F22-G22 -> 1816045.2 | I22: =H22-E22*הנחות!$B$7 -> 371520.35 | J22: =IFERROR(I22/F22,0) -> 0.16775281
A23: אוג 2027 | B23: 12 | C23: הרחבה | D23: =1*הנחות!$B$42 -> 0.1 | E23: =(הנחות!$B$22/12)*D23/(הנחות!$B$41/(1-הנחות!$B$15)*(1+הנחות!$B$13)) -> 253919.89 | F23: =E23*הנחות!$B$41 -> 2259887 | G23: =F23*הנחות!$B$16 -> 406779.66 | H23: =F23-G23 -> 1853107.3 | I23: =H23-E23*הנחות!$B$7 -> 379102.39 | J23: =IFERROR(I23/F23,0) -> 0.16775281
A24: תת-סיכומים רבעוניים — שנה 1
A25: רבעון | B25: חודשים | C25: יחידות | D25: הכנסות B2B | E25: רווח גולמי | F25: GM % | G25: הערה
A26: Q1 | B26: M1-M3 | C26: =SUM(E12:E14) -> 142195.14 | D26: =SUM(F12:F14) -> 1265536.7 | E26: =SUM(I12:I14) -> 212297.34 | F26: =IFERROR(E26/D26,0) -> 0.16775281
A27: Q2 | B27: M4-M6 | C27: =SUM(E15:E17) -> 449438.2 | D27: =SUM(F15:F17) -> 4000000 | E27: =SUM(I15:I17) -> 671011.24 | F27: =IFERROR(E27/D27,0) -> 0.16775281
A28: Q3 | B28: M7-M9 | C28: =SUM(E18:E20) -> 665270.11 | D28: =SUM(F18:F20) -> 5920904 | E28: =SUM(I18:I20) -> 993248.27 | F28: =IFERROR(E28/D28,0) -> 0.16775281
A29: Q4 | B29: M10-M12 | C29: =SUM(E21:E23) -> 743985.27 | D29: =SUM(F21:F23) -> 6621468.9 | E29: =SUM(I21:I23) -> 1110770 | F29: =IFERROR(E29/D29,0) -> 0.16775281
A31: סה״כ שנה 1 | E31: =SUM(E12:E23) -> 2000888.7 | F31: =SUM(F12:F23) -> 17807910 | G31: =SUM(G12:G23) -> 3205423.7 | H31: =SUM(H12:H23) -> 14602486 | I31: =SUM(I12:I23) -> 2987326.9 | J31: =IFERROR(I31/F31,0) -> 0.16775281
A33: C. תחזית חודשית — שנה 2 (ספט 2027 → אוג 2028) · פורמט 150g
A34: חודש | B34: M# | C34: שלב | D34: נתח יעד % | E34: יחידות | F34: הכנסות B2B | G34: עמלת מפיץ | H34: נטו ל-Raito | I34: רווח גולמי | J34: GM %
A35: ספט 2027 | B35: 13 | C35: הרחבה | D35: =הנחות!$B$42+(הנחות!$B$43-הנחות!$B$42)*0.0833333333333333 -> 0.10416667 | E35: =(הנחות!$B$22/12)*D35/(הנחות!$B$41/(1-הנחות!$B$15)*(1+הנחות!$B$13)) -> 264499.88 | F35: =E35*הנחות!$B$41 -> 2354049 | G35: =F35*הנחות!$B$16 -> 423728.81 | H35: =F35-G35 -> 1930320.2 | I35: =H35-E35*הנחות!$B$7 -> 394898.33 | J35: =IFERROR(I35/F35,0) -> 0.16775281
A36: אוק 2027 | B36: 14 | C36: הרחבה | D36: =הנחות!$B$42+(הנחות!$B$43-הנחות!$B$42)*0.166666666666667 -> 0.10833333 | E36: =(הנחות!$B$22/12)*D36/(הנחות!$B$41/(1-הנחות!$B$15)*(1+הנחות!$B$13)) -> 275079.88 | F36: =E36*הנחות!$B$41 -> 2448210.9 | G36: =F36*הנחות!$B$16 -> 440677.97 | H36: =F36-G36 -> 2007533 | I36: =H36-E36*הנחות!$B$7 -> 410694.26 | J36: =IFERROR(I36/F36,0) -> 0.16775281
A37: נוב 2027 | B37: 15 | C37: הרחבה | D37: =הנחות!$B$42+(הנחות!$B$43-הנחות!$B$42)*0.25 -> 0.1125 | E37: =(הנחות!$B$22/12)*D37/(הנחות!$B$41/(1-הנחות!$B$15)*(1+הנחות!$B$13)) -> 285659.87 | F37: =E37*הנחות!$B$41 -> 2542372.9 | G37: =F37*הנחות!$B$16 -> 457627.12 | H37: =F37-G37 -> 2084745.8 | I37: =H37-E37*הנחות!$B$7 -> 426490.19 | J37: =IFERROR(I37/F37,0) -> 0.16775281
A38: דצמ 2027 | B38: 16 | C38: הרחבה | D38: =הנחות!$B$42+(הנחות!$B$43-הנחות!$B$42)*0.333333333333333 -> 0.11666667 | E38: =(הנחות!$B$22/12)*D38/(הנחות!$B$41/(1-הנחות!$B$15)*(1+הנחות!$B$13)) -> 296239.87 | F38: =E38*הנחות!$B$41 -> 2636534.8 | G38: =F38*הנחות!$B$16 -> 474576.27 | H38: =F38-G38 -> 2161958.6 | I38: =H38-E38*הנחות!$B$7 -> 442286.13 | J38: =IFERROR(I38/F38,0) -> 0.16775281
A39: ינו 2028 | B39: 17 | C39: הרחבה | D39: =הנחות!$B$42+(הנחות!$B$43-הנחות!$B$42)*0.416666666666667 -> 0.12083333 | E39: =(הנחות!$B$22/12)*D39/(הנחות!$B$41/(1-הנחות!$B$15)*(1+הנחות!$B$13)) -> 306819.86 | F39: =E39*הנחות!$B$41 -> 2730696.8 | G39: =F39*הנחות!$B$16 -> 491525.42 | H39: =F39-G39 -> 2239171.4 | I39: =H39-E39*הנחות!$B$7 -> 458082.06 | J39: =IFERROR(I39/F39,0) -> 0.16775281
A40: פבר 2028 | B40: 18 | C40: הרחבה | D40: =הנחות!$B$42+(הנחות!$B$43-הנחות!$B$42)*0.5 -> 0.125 | E40: =(הנחות!$B$22/12)*D40/(הנחות!$B$41/(1-הנחות!$B$15)*(1+הנחות!$B$13)) -> 317399.86 | F40: =E40*הנחות!$B$41 -> 2824858.8 | G40: =F40*הנחות!$B$16 -> 508474.58 | H40: =F40-G40 -> 2316384.2 | I40: =H40-E40*הנחות!$B$7 -> 473877.99 | J40: =IFERROR(I40/F40,0) -> 0.16775281
A41: מרץ 2028 | B41: 19 | C41: בגרות | D41: =הנחות!$B$42+(הנחות!$B$43-הנחות!$B$42)*0.583333333333333 -> 0.12916667 | E41: =(הנחות!$B$22/12)*D41/(הנחות!$B$41/(1-הנחות!$B$15)*(1+הנחות!$B$13)) -> 327979.86 | F41: =E41*הנחות!$B$41 -> 2919020.7 | G41: =F41*הנחות!$B$16 -> 525423.73 | H41: =F41-G41 -> 2393597 | I41: =H41-E41*הנחות!$B$7 -> 489673.92 | J41: =IFERROR(I41/F41,0) -> 0.16775281
A42: אפר 2028 | B42: 20 | C42: בגרות | D42: =הנחות!$B$42+(הנחות!$B$43-הנחות!$B$42)*0.666666666666667 -> 0.13333333 | E42: =(הנחות!$B$22/12)*D42/(הנחות!$B$41/(1-הנחות!$B$15)*(1+הנחות!$B$13)) -> 338559.85 | F42: =E42*הנחות!$B$41 -> 3013182.7 | G42: =F42*הנחות!$B$16 -> 542372.88 | H42: =F42-G42 -> 2470809.8 | I42: =H42-E42*הנחות!$B$7 -> 505469.86 | J42: =IFERROR(I42/F42,0) -> 0.16775281
A43: מאי 2028 | B43: 21 | C43: בגרות | D43: =הנחות!$B$42+(הנחות!$B$43-הנחות!$B$42)*0.75 -> 0.1375 | E43: =(הנחות!$B$22/12)*D43/(הנחות!$B$41/(1-הנחות!$B$15)*(1+הנחות!$B$13)) -> 349139.85 | F43: =E43*הנחות!$B$41 -> 3107344.6 | G43: =F43*הנחות!$B$16 -> 559322.03 | H43: =F43-G43 -> 2548022.6 | I43: =H43-E43*הנחות!$B$7 -> 521265.79 | J43: =IFERROR(I43/F43,0) -> 0.16775281
A44: יונ 2028 | B44: 22 | C44: בגרות | D44: =הנחות!$B$42+(הנחות!$B$43-הנחות!$B$42)*0.833333333333333 -> 0.14166667 | E44: =(הנחות!$B$22/12)*D44/(הנחות!$B$41/(1-הנחות!$B$15)*(1+הנחות!$B$13)) -> 359719.84 | F44: =E44*הנחות!$B$41 -> 3201506.6 | G44: =F44*הנחות!$B$16 -> 576271.19 | H44: =F44-G44 -> 2625235.4 | I44: =H44-E44*הנחות!$B$7 -> 537061.72 | J44: =IFERROR(I44/F44,0) -> 0.16775281
...

Sheet תחזית 3x100 גרם
A1: תחזית מכירות חודשית — פורמט 3×100g · 24 חודשים
A2: ספט 2026 → אוג 2028 · B2B ₪19.5 (הנחות) · גודל שוק ₪400M טורקי (מ-תא C22)
A4: A. שלבי השקה (Phases) — הגדרת הנחות הרמפ
A5: שלב | B5: חודשים | C5: נתח יעד | D5: פעילות שיווק | E5: הערות
A6: השקה (Launch) | B6: M1-M6 | C6: 0-70% מ-M12 | D6: Ma Kashur content blitz, משפיענים, PR, דגימות | E6: בניית מודעות למותג, חשיפה של המוצר הערבי-ישראלי המקומי
A7: הרחבה (Expand) | B7: M7-M18 | C7: 70% → M24 target | D7: המשך תוכן, שיתופי פעולה, מבצעים עונתיים | E7: מיקוד על הרחבת הפצה לרשתות מאורגנות + צמיחה בשוק פרטי
A8: בגרות (Mature) | B8: M19-M24 | C8: יעד M24 מושג | D8: תחזוקה, מוצרי-המשך (flavors, packaging) | E8: שמירה על נתח, אופטימיזציה של עלויות ומרווחים
A10: B. תחזית חודשית — שנה 1 (ספט 2026 → אוג 2027) · פורמט 3×100g
A11: חודש | B11: M# | C11: שלב | D11: נתח יעד % | E11: יחידות | F11: הכנסות B2B | G11: עמלת מפיץ | H11: נטו ל-Raito | I11: רווח גולמי | J11: GM %
A12: ספט 2026 | B12: 1 | C12: השקה | D12: =0.08*הנחות!$B$47 -> 0.0032 | E12: =(הנחות!$B$22/12)*D12/(הנחות!$B$46/(1-הנחות!$B$15)*(1+הנחות!$B$13)) -> 3708.5325 | F12: =E12*הנחות!$B$46 -> 72316.384 | G12: =F12*הנחות!$B$16 -> 13016.949 | H12: =F12-G12 -> 59299.435 | I12: =H12-E12*הנחות!$B$8 -> 16243.372 | J12: =IFERROR(I12/F12,0) -> 0.22461538
A13: אוק 2026 | B13: 2 | C13: השקה | D13: =0.18*הנחות!$B$47 -> 0.0072 | E13: =(הנחות!$B$22/12)*D13/(הנחות!$B$46/(1-הנחות!$B$15)*(1+הנחות!$B$13)) -> 8344.1982 | F13: =E13*הנחות!$B$46 -> 162711.86 | G13: =F13*הנחות!$B$16 -> 29288.136 | H13: =F13-G13 -> 133423.73 | I13: =H13-E13*הנחות!$B$8 -> 36547.588 | J13: =IFERROR(I13/F13,0) -> 0.22461538
A14: נוב 2026 | B14: 3 | C14: השקה | D14: =0.3*הנחות!$B$47 -> 0.012 | E14: =(הנחות!$B$22/12)*D14/(הנחות!$B$46/(1-הנחות!$B$15)*(1+הנחות!$B$13)) -> 13906.997 | F14: =E14*הנחות!$B$46 -> 271186.44 | G14: =F14*הנחות!$B$16 -> 48813.559 | H14: =F14-G14 -> 222372.88 | I14: =H14-E14*הנחות!$B$8 -> 60912.647 | J14: =IFERROR(I14/F14,0) -> 0.22461538
A15: דצמ 2026 | B15: 4 | C15: השקה | D15: =0.45*הנחות!$B$47 -> 0.018 | E15: =(הנחות!$B$22/12)*D15/(הנחות!$B$46/(1-הנחות!$B$15)*(1+הנחות!$B$13)) -> 20860.495 | F15: =E15*הנחות!$B$46 -> 406779.66 | G15: =F15*הנחות!$B$16 -> 73220.339 | H15: =F15-G15 -> 333559.32 | I15: =H15-E15*הנחות!$B$8 -> 91368.97 | J15: =IFERROR(I15/F15,0) -> 0.22461538
A16: ינו 2027 | B16: 5 | C16: השקה | D16: =0.6*הנחות!$B$47 -> 0.024 | E16: =(הנחות!$B$22/12)*D16/(הנחות!$B$46/(1-הנחות!$B$15)*(1+הנחות!$B$13)) -> 27813.994 | F16: =E16*הנחות!$B$46 -> 542372.88 | G16: =F16*הנחות!$B$16 -> 97627.119 | H16: =F16-G16 -> 444745.76 | I16: =H16-E16*הנחות!$B$8 -> 121825.29 | J16: =IFERROR(I16/F16,0) -> 0.22461538
A17: פבר 2027 | B17: 6 | C17: השקה | D17: =0.72*הנחות!$B$47 -> 0.0288 | E17: =(הנחות!$B$22/12)*D17/(הנחות!$B$46/(1-הנחות!$B$15)*(1+הנחות!$B$13)) -> 33376.793 | F17: =E17*הנחות!$B$46 -> 650847.46 | G17: =F17*הנחות!$B$16 -> 117152.54 | H17: =F17-G17 -> 533694.92 | I17: =H17-E17*הנחות!$B$8 -> 146190.35 | J17: =IFERROR(I17/F17,0) -> 0.22461538
A18: מרץ 2027 | B18: 7 | C18: הרחבה | D18: =0.82*הנחות!$B$47 -> 0.0328 | E18: =(הנחות!$B$22/12)*D18/(הנחות!$B$46/(1-הנחות!$B$15)*(1+הנחות!$B$13)) -> 38012.458 | F18: =E18*הנחות!$B$46 -> 741242.94 | G18: =F18*הנחות!$B$16 -> 133423.73 | H18: =F18-G18 -> 607819.21 | I18: =H18-E18*הנחות!$B$8 -> 166494.57 | J18: =IFERROR(I18/F18,0) -> 0.22461538
A19: אפר 2027 | B19: 8 | C19: הרחבה | D19: =0.88*הנחות!$B$47 -> 0.0352 | E19: =(הנחות!$B$22/12)*D19/(הנחות!$B$46/(1-הנחות!$B$15)*(1+הנחות!$B$13)) -> 40793.858 | F19: =E19*הנחות!$B$46 -> 795480.23 | G19: =F19*הנחות!$B$16 -> 143186.44 | H19: =F19-G19 -> 652293.79 | I19: =H19-E19*הנחות!$B$8 -> 178677.1 | J19: =IFERROR(I19/F19,0) -> 0.22461538
A20: מאי 2027 | B20: 9 | C20: הרחבה | D20: =0.92*הנחות!$B$47 -> 0.0368 | E20: =(הנחות!$B$22/12)*D20/(הנחות!$B$46/(1-הנחות!$B$15)*(1+הנחות!$B$13)) -> 42648.124 | F20: =E20*הנחות!$B$46 -> 831638.42 | G20: =F20*הנחות!$B$16 -> 149694.92 | H20: =F20-G20 -> 681943.5 | I20: =H20-E20*הנחות!$B$8 -> 186798.78 | J20: =IFERROR(I20/F20,0) -> 0.22461538
A21: יונ 2027 | B21: 10 | C21: הרחבה | D21: =0.95*הנחות!$B$47 -> 0.038 | E21: =(הנחות!$B$22/12)*D21/(הנחות!$B$46/(1-הנחות!$B$15)*(1+הנחות!$B$13)) -> 44038.824 | F21: =E21*הנחות!$B$46 -> 858757.06 | G21: =F21*הנחות!$B$16 -> 154576.27 | H21: =F21-G21 -> 704180.79 | I21: =H21-E21*הנחות!$B$8 -> 192890.05 | J21: =IFERROR(I21/F21,0) -> 0.22461538
A22: יול 2027 | B22: 11 | C22: הרחבה | D22: =0.98*הנחות!$B$47 -> 0.0392 | E22: =(הנחות!$B$22/12)*D22/(הנחות!$B$46/(1-הנחות!$B$15)*(1+הנחות!$B$13)) -> 45429.523 | F22: =E22*הנחות!$B$46 -> 885875.71 | G22: =F22*הנחות!$B$16 -> 159457.63 | H22: =F22-G22 -> 726418.08 | I22: =H22-E22*הנחות!$B$8 -> 198981.31 | J22: =IFERROR(I22/F22,0) -> 0.22461538
A23: אוג 2027 | B23: 12 | C23: הרחבה | D23: =1*הנחות!$B$47 -> 0.04 | E23: =(הנחות!$B$22/12)*D23/(הנחות!$B$46/(1-הנחות!$B$15)*(1+הנחות!$B$13)) -> 46356.657 | F23: =E23*הנחות!$B$46 -> 903954.8 | G23: =F23*הנחות!$B$16 -> 162711.86 | H23: =F23-G23 -> 741242.94 | I23: =H23-E23*הנחות!$B$8 -> 203042.16 | J23: =IFERROR(I23/F23,0) -> 0.22461538
A24: תת-סיכומים רבעוניים — שנה 1
A25: רבעון | B25: חודשים | C25: יחידות | D25: הכנסות B2B | E25: רווח גולמי | F25: GM % | G25: הערה
A26: Q1 | B26: M1-M3 | C26: =SUM(E12:E14) -> 25959.728 | D26: =SUM(F12:F14) -> 506214.69 | E26: =SUM(I12:I14) -> 113703.61 | F26: =IFERROR(E26/D26,0) -> 0.22461538
A27: Q2 | B27: M4-M6 | C27: =SUM(E15:E17) -> 82051.282 | D27: =SUM(F15:F17) -> 1600000 | E27: =SUM(I15:I17) -> 359384.62 | F27: =IFERROR(E27/D27,0) -> 0.22461538
A28: Q3 | B28: M7-M9 | C28: =SUM(E18:E20) -> 121454.44 | D28: =SUM(F18:F20) -> 2368361.6 | E28: =SUM(I18:I20) -> 531970.45 | F28: =IFERROR(E28/D28,0) -> 0.22461538
A29: Q4 | B29: M10-M12 | C29: =SUM(E21:E23) -> 135825 | D29: =SUM(F21:F23) -> 2648587.6 | E29: =SUM(I21:I23) -> 594913.52 | F29: =IFERROR(E29/D29,0) -> 0.22461538
A31: סה״כ שנה 1 | E31: =SUM(E12:E23) -> 365290.45 | F31: =SUM(F12:F23) -> 7123163.8 | G31: =SUM(G12:G23) -> 1282169.5 | H31: =SUM(H12:H23) -> 5840994.4 | I31: =SUM(I12:I23) -> 1599972.2 | J31: =IFERROR(I31/F31,0) -> 0.22461538
A33: C. תחזית חודשית — שנה 2 (ספט 2027 → אוג 2028) · פורמט 3×100g
A34: חודש | B34: M# | C34: שלב | D34: נתח יעד % | E34: יחידות | F34: הכנסות B2B | G34: עמלת מפיץ | H34: נטו ל-Raito | I34: רווח גולמי | J34: GM %
A35: ספט 2027 | B35: 13 | C35: הרחבה | D35: =הנחות!$B$47+(הנחות!$B$48-הנחות!$B$47)*0.0833333333333333 -> 0.0425 | E35: =(הנחות!$B$22/12)*D35/(הנחות!$B$46/(1-הנחות!$B$15)*(1+הנחות!$B$13)) -> 49253.948 | F35: =E35*הנחות!$B$46 -> 960451.98 | G35: =F35*הנחות!$B$16 -> 172881.36 | H35: =F35-G35 -> 787570.62 | I35: =H35-E35*הנחות!$B$8 -> 215732.29 | J35: =IFERROR(I35/F35,0) -> 0.22461538
A36: אוק 2027 | B36: 14 | C36: הרחבה | D36: =הנחות!$B$47+(הנחות!$B$48-הנחות!$B$47)*0.166666666666667 -> 0.045 | E36: =(הנחות!$B$22/12)*D36/(הנחות!$B$46/(1-הנחות!$B$15)*(1+הנחות!$B$13)) -> 52151.239 | F36: =E36*הנחות!$B$46 -> 1016949.2 | G36: =F36*הנחות!$B$16 -> 183050.85 | H36: =F36-G36 -> 833898.31 | I36: =H36-E36*הנחות!$B$8 -> 228422.43 | J36: =IFERROR(I36/F36,0) -> 0.22461538
A37: נוב 2027 | B37: 15 | C37: הרחבה | D37: =הנחות!$B$47+(הנחות!$B$48-הנחות!$B$47)*0.25 -> 0.0475 | E37: =(הנחות!$B$22/12)*D37/(הנחות!$B$46/(1-הנחות!$B$15)*(1+הנחות!$B$13)) -> 55048.53 | F37: =E37*הנחות!$B$46 -> 1073446.3 | G37: =F37*הנחות!$B$16 -> 193220.34 | H37: =F37-G37 -> 880225.99 | I37: =H37-E37*הנחות!$B$8 -> 241112.56 | J37: =IFERROR(I37/F37,0) -> 0.22461538
A38: דצמ 2027 | B38: 16 | C38: הרחבה | D38: =הנחות!$B$47+(הנחות!$B$48-הנחות!$B$47)*0.333333333333333 -> 0.05 | E38: =(הנחות!$B$22/12)*D38/(הנחות!$B$46/(1-הנחות!$B$15)*(1+הנחות!$B$13)) -> 57945.821 | F38: =E38*הנחות!$B$46 -> 1129943.5 | G38: =F38*הנחות!$B$16 -> 203389.83 | H38: =F38-G38 -> 926553.67 | I38: =H38-E38*הנחות!$B$8 -> 253802.69 | J38: =IFERROR(I38/F38,0) -> 0.22461538
A39: ינו 2028 | B39: 17 | C39: הרחבה | D39: =הנחות!$B$47+(הנחות!$B$48-הנחות!$B$47)*0.416666666666667 -> 0.0525 | E39: =(הנחות!$B$22/12)*D39/(הנחות!$B$46/(1-הנחות!$B$15)*(1+הנחות!$B$13)) -> 60843.112 | F39: =E39*הנחות!$B$46 -> 1186440.7 | G39: =F39*הנחות!$B$16 -> 213559.32 | H39: =F39-G39 -> 972881.36 | I39: =H39-E39*הנחות!$B$8 -> 266492.83 | J39: =IFERROR(I39/F39,0) -> 0.22461538
A40: פבר 2028 | B40: 18 | C40: הרחבה | D40: =הנחות!$B$47+(הנחות!$B$48-הנחות!$B$47)*0.5 -> 0.055 | E40: =(הנחות!$B$22/12)*D40/(הנחות!$B$46/(1-הנחות!$B$15)*(1+הנחות!$B$13)) -> 63740.403 | F40: =E40*הנחות!$B$46 -> 1242937.9 | G40: =F40*הנחות!$B$16 -> 223728.81 | H40: =F40-G40 -> 1019209 | I40: =H40-E40*הנחות!$B$8 -> 279182.96 | J40: =IFERROR(I40/F40,0) -> 0.22461538
A41: מרץ 2028 | B41: 19 | C41: בגרות | D41: =הנחות!$B$47+(הנחות!$B$48-הנחות!$B$47)*0.583333333333333 -> 0.0575 | E41: =(הנחות!$B$22/12)*D41/(הנחות!$B$46/(1-הנחות!$B$15)*(1+הנחות!$B$13)) -> 66637.694 | F41: =E41*הנחות!$B$46 -> 1299435 | G41: =F41*הנחות!$B$16 -> 233898.31 | H41: =F41-G41 -> 1065536.7 | I41: =H41-E41*הנחות!$B$8 -> 291873.1 | J41: =IFERROR(I41/F41,0) -> 0.22461538
A42: אפר 2028 | B42: 20 | C42: בגרות | D42: =הנחות!$B$47+(הנחות!$B$48-הנחות!$B$47)*0.666666666666667 -> 0.06 | E42: =(הנחות!$B$22/12)*D42/(הנחות!$B$46/(1-הנחות!$B$15)*(1+הנחות!$B$13)) -> 69534.985 | F42: =E42*הנחות!$B$46 -> 1355932.2 | G42: =F42*הנחות!$B$16 -> 244067.8 | H42: =F42-G42 -> 1111864.4 | I42: =H42-E42*הנחות!$B$8 -> 304563.23 | J42: =IFERROR(I42/F42,0) -> 0.22461538
A43: מאי 2028 | B43: 21 | C43: בגרות | D43: =הנחות!$B$47+(הנחות!$B$48-הנחות!$B$47)*0.75 -> 0.0625 | E43: =(הנחות!$B$22/12)*D43/(הנחות!$B$46/(1-הנחות!$B$15)*(1+הנחות!$B$13)) -> 72432.276 | F43: =E43*הנחות!$B$46 -> 1412429.4 | G43: =F43*הנחות!$B$16 -> 254237.29 | H43: =F43-G43 -> 1158192.1 | I43: =H43-E43*הנחות!$B$8 -> 317253.37 | J43: =IFERROR(I43/F43,0) -> 0.22461538
A44: יונ 2028 | B44: 22 | C44: בגרות | D44: =הנחות!$B$47+(הנחות!$B$48-הנחות!$B$47)*0.833333333333333 -> 0.065 | E44: =(הנחות!$B$22/12)*D44/(הנחות!$B$46/(1-הנחות!$B$15)*(1+הנחות!$B$13)) -> 75329.567 | F44: =E44*הנחות!$B$46 -> 1468926.6 | G44: =F44*הנחות!$B$16 -> 264406.78 | H44: =F44-G44 -> 1204519.8 | I44: =H44-E44*הנחות!$B$8 -> 329943.5 | J44: =IFERROR(I44/F44,0) -> 0.22461538
...

Sheet תחזית 100 גרם
A1: תחזית מכירות חודשית — פורמט 100g · 24 חודשים
A2: ספט 2026 → אוג 2028 · B2B ₪6.5 (הנחות) · גודל שוק ₪400M טורקי (מ-תא C22)
A4: A. שלבי השקה (Phases) — הגדרת הנחות הרמפ
A5: שלב | B5: חודשים | C5: נתח יעד | D5: פעילות שיווק | E5: הערות
A6: השקה (Launch) | B6: M1-M6 | C6: 0-70% מ-M12 | D6: Ma Kashur content blitz, משפיענים, PR, דגימות | E6: בניית מודעות למותג, חשיפה של המוצר הערבי-ישראלי המקומי
A7: הרחבה (Expand) | B7: M7-M18 | C7: 70% → M24 target | D7: המשך תוכן, שיתופי פעולה, מבצעים עונתיים | E7: מיקוד על הרחבת הפצה לרשתות מאורגנות + צמיחה בשוק פרטי
A8: בגרות (Mature) | B8: M19-M24 | C8: יעד M24 מושג | D8: תחזוקה, מוצרי-המשך (flavors, packaging) | E8: שמירה על נתח, אופטימיזציה של עלויות ומרווחים
A10: B. תחזית חודשית — שנה 1 (ספט 2026 → אוג 2027) · פורמט 100g
A11: חודש | B11: M# | C11: שלב | D11: נתח יעד % | E11: יחידות | F11: הכנסות B2B | G11: עמלת מפיץ | H11: נטו ל-Raito | I11: רווח גולמי | J11: GM %
A12: ספט 2026 | B12: 1 | C12: השקה | D12: =0.08*הנחות!$B$52 -> 0.0048 | E12: =(הנחות!$B$22/12)*D12/(הנחות!$B$51/(1-הנחות!$B$15)*(1+הנחות!$B$13)) -> 16688.396 | F12: =E12*הנחות!$B$51 -> 108474.58 | G12: =F12*הנחות!$B$16 -> 19525.424 | H12: =F12-G12 -> 88949.153 | I12: =H12-E12*הנחות!$B$9 -> 24365.059 | J12: =IFERROR(I12/F12,0) -> 0.22461538
A13: אוק 2026 | B13: 2 | C13: השקה | D13: =0.18*הנחות!$B$52 -> 0.0108 | E13: =(הנחות!$B$22/12)*D13/(הנחות!$B$51/(1-הנחות!$B$15)*(1+הנחות!$B$13)) -> 37548.892 | F13: =E13*הנחות!$B$51 -> 244067.8 | G13: =F13*הנחות!$B$16 -> 43932.203 | H13: =F13-G13 -> 200135.59 | I13: =H13-E13*הנחות!$B$9 -> 54821.382 | J13: =IFERROR(I13/F13,0) -> 0.22461538
A14: נוב 2026 | B14: 3 | C14: השקה | D14: =0.3*הנחות!$B$52 -> 0.018 | E14: =(הנחות!$B$22/12)*D14/(הנחות!$B$51/(1-הנחות!$B$15)*(1+הנחות!$B$13)) -> 62581.486 | F14: =E14*הנחות!$B$51 -> 406779.66 | G14: =F14*הנחות!$B$16 -> 73220.339 | H14: =F14-G14 -> 333559.32 | I14: =H14-E14*הנחות!$B$9 -> 91368.97 | J14: =IFERROR(I14/F14,0) -> 0.22461538
A15: דצמ 2026 | B15: 4 | C15: השקה | D15: =0.45*הנחות!$B$52 -> 0.027 | E15: =(הנחות!$B$22/12)*D15/(הנחות!$B$51/(1-הנחות!$B$15)*(1+הנחות!$B$13)) -> 93872.229 | F15: =E15*הנחות!$B$51 -> 610169.49 | G15: =F15*הנחות!$B$16 -> 109830.51 | H15: =F15-G15 -> 500338.98 | I15: =H15-E15*הנחות!$B$9 -> 137053.46 | J15: =IFERROR(I15/F15,0) -> 0.22461538
A16: ינו 2027 | B16: 5 | C16: השקה | D16: =0.6*הנחות!$B$52 -> 0.036 | E16: =(הנחות!$B$22/12)*D16/(הנחות!$B$51/(1-הנחות!$B$15)*(1+הנחות!$B$13)) -> 125162.97 | F16: =E16*הנחות!$B$51 -> 813559.32 | G16: =F16*הנחות!$B$16 -> 146440.68 | H16: =F16-G16 -> 667118.64 | I16: =H16-E16*הנחות!$B$9 -> 182737.94 | J16: =IFERROR(I16/F16,0) -> 0.22461538
A17: פבר 2027 | B17: 6 | C17: השקה | D17: =0.72*הנחות!$B$52 -> 0.0432 | E17: =(הנחות!$B$22/12)*D17/(הנחות!$B$51/(1-הנחות!$B$15)*(1+הנחות!$B$13)) -> 150195.57 | F17: =E17*הנחות!$B$51 -> 976271.19 | G17: =F17*הנחות!$B$16 -> 175728.81 | H17: =F17-G17 -> 800542.37 | I17: =H17-E17*הנחות!$B$9 -> 219285.53 | J17: =IFERROR(I17/F17,0) -> 0.22461538
A18: מרץ 2027 | B18: 7 | C18: הרחבה | D18: =0.82*הנחות!$B$52 -> 0.0492 | E18: =(הנחות!$B$22/12)*D18/(הנחות!$B$51/(1-הנחות!$B$15)*(1+הנחות!$B$13)) -> 171056.06 | F18: =E18*הנחות!$B$51 -> 1111864.4 | G18: =F18*הנחות!$B$16 -> 200135.59 | H18: =F18-G18 -> 911728.81 | I18: =H18-E18*הנחות!$B$9 -> 249741.85 | J18: =IFERROR(I18/F18,0) -> 0.22461538
A19: אפר 2027 | B19: 8 | C19: הרחבה | D19: =0.88*הנחות!$B$52 -> 0.0528 | E19: =(הנחות!$B$22/12)*D19/(הנחות!$B$51/(1-הנחות!$B$15)*(1+הנחות!$B$13)) -> 183572.36 | F19: =E19*הנחות!$B$51 -> 1193220.3 | G19: =F19*הנחות!$B$16 -> 214779.66 | H19: =F19-G19 -> 978440.68 | I19: =H19-E19*הנחות!$B$9 -> 268015.65 | J19: =IFERROR(I19/F19,0) -> 0.22461538
A20: מאי 2027 | B20: 9 | C20: הרחבה | D20: =0.92*הנחות!$B$52 -> 0.0552 | E20: =(הנחות!$B$22/12)*D20/(הנחות!$B$51/(1-הנחות!$B$15)*(1+הנחות!$B$13)) -> 191916.56 | F20: =E20*הנחות!$B$51 -> 1247457.6 | G20: =F20*הנחות!$B$16 -> 224542.37 | H20: =F20-G20 -> 1022915.3 | I20: =H20-E20*הנחות!$B$9 -> 280198.17 | J20: =IFERROR(I20/F20,0) -> 0.22461538
A21: יונ 2027 | B21: 10 | C21: הרחבה | D21: =0.95*הנחות!$B$52 -> 0.057 | E21: =(הנחות!$B$22/12)*D21/(הנחות!$B$51/(1-הנחות!$B$15)*(1+הנחות!$B$13)) -> 198174.71 | F21: =E21*הנחות!$B$51 -> 1288135.6 | G21: =F21*הנחות!$B$16 -> 231864.41 | H21: =F21-G21 -> 1056271.2 | I21: =H21-E21*הנחות!$B$9 -> 289335.07 | J21: =IFERROR(I21/F21,0) -> 0.22461538
A22: יול 2027 | B22: 11 | C22: הרחבה | D22: =0.98*הנחות!$B$52 -> 0.0588 | E22: =(הנחות!$B$22/12)*D22/(הנחות!$B$51/(1-הנחות!$B$15)*(1+הנחות!$B$13)) -> 204432.86 | F22: =E22*הנחות!$B$51 -> 1328813.6 | G22: =F22*הנחות!$B$16 -> 239186.44 | H22: =F22-G22 -> 1089627.1 | I22: =H22-E22*הנחות!$B$9 -> 298471.97 | J22: =IFERROR(I22/F22,0) -> 0.22461538
A23: אוג 2027 | B23: 12 | C23: הרחבה | D23: =1*הנחות!$B$52 -> 0.06 | E23: =(הנחות!$B$22/12)*D23/(הנחות!$B$51/(1-הנחות!$B$15)*(1+הנחות!$B$13)) -> 208604.95 | F23: =E23*הנחות!$B$51 -> 1355932.2 | G23: =F23*הנחות!$B$16 -> 244067.8 | H23: =F23-G23 -> 1111864.4 | I23: =H23-E23*הנחות!$B$9 -> 304563.23 | J23: =IFERROR(I23/F23,0) -> 0.22461538
A24: תת-סיכומים רבעוניים — שנה 1
A25: רבעון | B25: חודשים | C25: יחידות | D25: הכנסות B2B | E25: רווח גולמי | F25: GM % | G25: הערה
A26: Q1 | B26: M1-M3 | C26: =SUM(E12:E14) -> 116818.77 | D26: =SUM(F12:F14) -> 759322.03 | E26: =SUM(I12:I14) -> 170555.41 | F26: =IFERROR(E26/D26,0) -> 0.22461538
A27: Q2 | B27: M4-M6 | C27: =SUM(E15:E17) -> 369230.77 | D27: =SUM(F15:F17) -> 2400000 | E27: =SUM(I15:I17) -> 539076.92 | F27: =IFERROR(E27/D27,0) -> 0.22461538
A28: Q3 | B28: M7-M9 | C28: =SUM(E18:E20) -> 546544.98 | D28: =SUM(F18:F20) -> 3552542.4 | E28: =SUM(I18:I20) -> 797955.67 | F28: =IFERROR(E28/D28,0) -> 0.22461538
A29: Q4 | B29: M10-M12 | C29: =SUM(E21:E23) -> 611212.52 | D29: =SUM(F21:F23) -> 3972881.4 | E29: =SUM(I21:I23) -> 892370.27 | F29: =IFERROR(E29/D29,0) -> 0.22461538
A31: סה״כ שנה 1 | E31: =SUM(E12:E23) -> 1643807 | F31: =SUM(F12:F23) -> 10684746 | G31: =SUM(G12:G23) -> 1923254.2 | H31: =SUM(H12:H23) -> 8761491.5 | I31: =SUM(I12:I23) -> 2399958.3 | J31: =IFERROR(I31/F31,0) -> 0.22461538
A33: C. תחזית חודשית — שנה 2 (ספט 2027 → אוג 2028) · פורמט 100g
A34: חודש | B34: M# | C34: שלב | D34: נתח יעד % | E34: יחידות | F34: הכנסות B2B | G34: עמלת מפיץ | H34: נטו ל-Raito | I34: רווח גולמי | J34: GM %
A35: ספט 2027 | B35: 13 | C35: הרחבה | D35: =הנחות!$B$52+(הנחות!$B$53-הנחות!$B$52)*0.0833333333333333 -> 0.0625 | E35: =(הנחות!$B$22/12)*D35/(הנחות!$B$51/(1-הנחות!$B$15)*(1+הנחות!$B$13)) -> 217296.83 | F35: =E35*הנחות!$B$51 -> 1412429.4 | G35: =F35*הנחות!$B$16 -> 254237.29 | H35: =F35-G35 -> 1158192.1 | I35: =H35-E35*הנחות!$B$9 -> 317253.37 | J35: =IFERROR(I35/F35,0) -> 0.22461538
A36: אוק 2027 | B36: 14 | C36: הרחבה | D36: =הנחות!$B$52+(הנחות!$B$53-הנחות!$B$52)*0.166666666666667 -> 0.065 | E36: =(הנחות!$B$22/12)*D36/(הנחות!$B$51/(1-הנחות!$B$15)*(1+הנחות!$B$13)) -> 225988.7 | F36: =E36*הנחות!$B$51 -> 1468926.6 | G36: =F36*הנחות!$B$16 -> 264406.78 | H36: =F36-G36 -> 1204519.8 | I36: =H36-E36*הנחות!$B$9 -> 329943.5 | J36: =IFERROR(I36/F36,0) -> 0.22461538
A37: נוב 2027 | B37: 15 | C37: הרחבה | D37: =הנחות!$B$52+(הנחות!$B$53-הנחות!$B$52)*0.25 -> 0.0675 | E37: =(הנחות!$B$22/12)*D37/(הנחות!$B$51/(1-הנחות!$B$15)*(1+הנחות!$B$13)) -> 234680.57 | F37: =E37*הנחות!$B$51 -> 1525423.7 | G37: =F37*הנחות!$B$16 -> 274576.27 | H37: =F37-G37 -> 1250847.5 | I37: =H37-E37*הנחות!$B$9 -> 342633.64 | J37: =IFERROR(I37/F37,0) -> 0.22461538
A38: דצמ 2027 | B38: 16 | C38: הרחבה | D38: =הנחות!$B$52+(הנחות!$B$53-הנחות!$B$52)*0.333333333333333 -> 0.07 | E38: =(הנחות!$B$22/12)*D38/(הנחות!$B$51/(1-הנחות!$B$15)*(1+הנחות!$B$13)) -> 243372.45 | F38: =E38*הנחות!$B$51 -> 1581920.9 | G38: =F38*הנחות!$B$16 -> 284745.76 | H38: =F38-G38 -> 1297175.1 | I38: =H38-E38*הנחות!$B$9 -> 355323.77 | J38: =IFERROR(I38/F38,0) -> 0.22461538
A39: ינו 2028 | B39: 17 | C39: הרחבה | D39: =הנחות!$B$52+(הנחות!$B$53-הנחות!$B$52)*0.416666666666667 -> 0.0725 | E39: =(הנחות!$B$22/12)*D39/(הנחות!$B$51/(1-הנחות!$B$15)*(1+הנחות!$B$13)) -> 252064.32 | F39: =E39*הנחות!$B$51 -> 1638418.1 | G39: =F39*הנחות!$B$16 -> 294915.25 | H39: =F39-G39 -> 1343502.8 | I39: =H39-E39*הנחות!$B$9 -> 368013.91 | J39: =IFERROR(I39/F39,0) -> 0.22461538
A40: פבר 2028 | B40: 18 | C40: הרחבה | D40: =הנחות!$B$52+(הנחות!$B$53-הנחות!$B$52)*0.5 -> 0.075 | E40: =(הנחות!$B$22/12)*D40/(הנחות!$B$51/(1-הנחות!$B$15)*(1+הנחות!$B$13)) -> 260756.19 | F40: =E40*הנחות!$B$51 -> 1694915.3 | G40: =F40*הנחות!$B$16 -> 305084.75 | H40: =F40-G40 -> 1389830.5 | I40: =H40-E40*הנחות!$B$9 -> 380704.04 | J40: =IFERROR(I40/F40,0) -> 0.22461538
A41: מרץ 2028 | B41: 19 | C41: בגרות | D41: =הנחות!$B$52+(הנחות!$B$53-הנחות!$B$52)*0.583333333333333 -> 0.0775 | E41: =(הנחות!$B$22/12)*D41/(הנחות!$B$51/(1-הנחות!$B$15)*(1+הנחות!$B$13)) -> 269448.07 | F41: =E41*הנחות!$B$51 -> 1751412.4 | G41: =F41*הנחות!$B$16 -> 315254.24 | H41: =F41-G41 -> 1436158.2 | I41: =H41-E41*הנחות!$B$9 -> 393394.18 | J41: =IFERROR(I41/F41,0) -> 0.22461538
A42: אפר 2028 | B42: 20 | C42: בגרות | D42: =הנחות!$B$52+(הנחות!$B$53-הנחות!$B$52)*0.666666666666667 -> 0.08 | E42: =(הנחות!$B$22/12)*D42/(הנחות!$B$51/(1-הנחות!$B$15)*(1+הנחות!$B$13)) -> 278139.94 | F42: =E42*הנחות!$B$51 -> 1807909.6 | G42: =F42*הנחות!$B$16 -> 325423.73 | H42: =F42-G42 -> 1482485.9 | I42: =H42-E42*הנחות!$B$9 -> 406084.31 | J42: =IFERROR(I42/F42,0) -> 0.22461538
A43: מאי 2028 | B43: 21 | C43: בגרות | D43: =הנחות!$B$52+(הנחות!$B$53-הנחות!$B$52)*0.75 -> 0.0825 | E43: =(הנחות!$B$22/12)*D43/(הנחות!$B$51/(1-הנחות!$B$15)*(1+הנחות!$B$13)) -> 286831.81 | F43: =E43*הנחות!$B$51 -> 1864406.8 | G43: =F43*הנחות!$B$16 -> 335593.22 | H43: =F43-G43 -> 1528813.6 | I43: =H43-E43*הנחות!$B$9 -> 418774.45 | J43: =IFERROR(I43/F43,0) -> 0.22461538
A44: יונ 2028 | B44: 22 | C44: בגרות | D44: =הנחות!$B$52+(הנחות!$B$53-הנחות!$B$52)*0.833333333333333 -> 0.085 | E44: =(הנחות!$B$22/12)*D44/(הנחות!$B$51/(1-הנחות!$B$15)*(1+הנחות!$B$13)) -> 295523.69 | F44: =E44*הנחות!$B$51 -> 1920904 | G44: =F44*הנחות!$B$16 -> 345762.71 | H44: =F44-G44 -> 1575141.2 | I44: =H44-E44*הנחות!$B$9 -> 431464.58 | J44: =IFERROR(I44/F44,0) -> 0.22461538
...

Sheet רווח והפסד
A1: רווח והפסד (P&L) — השוואת 3 פורמטים
A2: כל פורמט מוצג כתרחיש עצמאי (מקבל 100% מתקציב השיווק). סימולציה השוואתית על בסיס אחיד.
A4: A. דוח רווח והפסד — 2 שנות פעילות · הנתונים מקושרים לתחזיות
A5: סעיף | B5: תקופה | C5: הסבר | D5: 150g | E5: 3×100g | F5: 100g
A6: הכנסות B2B (Raito) | B6: שנה 1 | C6: חשבוניות Raito למפיץ (מעיין) | D6: ='תחזית 150 גרם'!F31 -> 17807910 | E6: ='תחזית 3x100 גרם'!F31 -> 7123163.8 | F6: ='תחזית 100 גרם'!F31 -> 10684746
A7: הכנסות B2B (Raito) | B7: שנה 2 | C7: חשבוניות Raito למפיץ | D7: ='תחזית 150 גרם'!F56 -> 34463277 | E7: ='תחזית 3x100 גרם'!F56 -> 15254237 | F7: ='תחזית 100 גרם'!F56 -> 20677966
A8: (-) עמלת מפיץ מעיין | B8: שנה 1 | C8: 18% מהכנסות B2B | D8: =-'תחזית 150 גרם'!G31 -> -3205423.7 | E8: =-'תחזית 3x100 גרם'!G31 -> -1282169.5 | F8: =-'תחזית 100 גרם'!G31 -> -1923254.2
A9: (-) עמלת מפיץ מעיין | B9: שנה 2 | C9: 18% מהכנסות B2B | D9: =-'תחזית 150 גרם'!G56 -> -6203389.8 | E9: =-'תחזית 3x100 גרם'!G56 -> -2745762.7 | F9: =-'תחזית 100 גרם'!G56 -> -3722033.9
A10: הכנסות נטו | B10: שנה 1 | C10: B2B − עמלת מפיץ | D10: ='תחזית 150 גרם'!H31 -> 14602486 | E10: ='תחזית 3x100 גרם'!H31 -> 5840994.4 | F10: ='תחזית 100 גרם'!H31 -> 8761491.5
A11: הכנסות נטו | B11: שנה 2 | C11: B2B − עמלת מפיץ | D11: ='תחזית 150 גרם'!H56 -> 28259887 | E11: ='תחזית 3x100 גרם'!H56 -> 12508475 | F11: ='תחזית 100 גרם'!H56 -> 16955932
A12: (-) עלות ייצור (COGS) | B12: שנה 1 | C12: יחידות × עלות/יחידה | D12: =-'תחזית 150 גרם'!E31*הנחות!$B$7 -> -11615159 | E12: =-'תחזית 3x100 גרם'!E31*הנחות!$B$8 -> -4241022.2 | F12: =-'תחזית 100 גרם'!E31*הנחות!$B$9 -> -6361533.2
A13: (-) עלות ייצור (COGS) | B13: שנה 2 | C13: יחידות × עלות/יחידה | D13: =-'תחזית 150 גרם'!E56*הנחות!$B$7 -> -22478576 | E13: =-'תחזית 3x100 גרם'!E56*הנחות!$B$8 -> -9082138.2 | F13: =-'תחזית 100 גרם'!E56*הנחות!$B$9 -> -12311343
A14: רווח גולמי | B14: שנה 1 | C14: הכנסות נטו − COGS | D14: ='תחזית 150 גרם'!I31 -> 2987326.9 | E14: ='תחזית 3x100 גרם'!I31 -> 1599972.2 | F14: ='תחזית 100 גרם'!I31 -> 2399958.3
A15: רווח גולמי | B15: שנה 2 | C15: הכנסות נטו − COGS | D15: ='תחזית 150 גרם'!I56 -> 5781311.5 | E15: ='תחזית 3x100 גרם'!I56 -> 3426336.4 | F15: ='תחזית 100 גרם'!I56 -> 4644589.3
A16: (-) שיווק (חלק Raito) | B16: שנה 1 | C16: 60% מתקציב 24 חודשים × 50% חלק Raito | D16: =-הנחות!$B$32*הנחות!$B$33*0.6 -> -225000 | E16: =-הנחות!$B$32*הנחות!$B$33*0.6 -> -225000 | F16: =-הנחות!$B$32*הנחות!$B$33*0.6 -> -225000
A17: EBITDA (תפעולי) | B17: שנה 1 | C17: רווח גולמי − שיווק | D17: =D14+D16 -> 2762326.9 | E17: =E14+E16 -> 1374972.2 | F17: =F14+F16 -> 2174958.3
A18: EBITDA (תפעולי) | B18: שנה 2 | C18: רווח גולמי שנה 2 − שיווק שנה 2 (40%) | D18: =D15+-הנחות!$B$32*הנחות!$B$33*0.4 -> 5631311.5 | E18: =E15+-הנחות!$B$32*הנחות!$B$33*0.4 -> 3276336.4 | F18: =F15+-הנחות!$B$32*הנחות!$B$33*0.4 -> 4494589.3
A19: סה״כ 2 שנים | B19: Y1+Y2 | C19: סה״כ EBITDA תקופה | D19: =D17+D18 -> 8393638.4 | E19: =E17+E18 -> 4651308.6 | F19: =F17+F18 -> 6669547.6
A21: B. יחסי רווחיות (KPIs)
A22: מרווח גולמי % (GM) | B22: שנה 1 | C22: רווח גולמי ÷ הכנסות B2B | D22: ='תחזית 150 גרם'!J31 -> 0.16775281 | E22: ='תחזית 3x100 גרם'!J31 -> 0.22461538 | F22: ='תחזית 100 גרם'!J31 -> 0.22461538
A23: מרווח גולמי % (GM) | B23: שנה 2 | C23: רווח גולמי ÷ הכנסות B2B | D23: ='תחזית 150 גרם'!J56 -> 0.16775281 | E23: ='תחזית 3x100 גרם'!J56 -> 0.22461538 | F23: ='תחזית 100 גרם'!J56 -> 0.22461538
A24: שולי EBITDA % (Y1) | B24: שנה 1 | C24: EBITDA ÷ הכנסות B2B | D24: =IFERROR(D17/D6,0) -> 0.15511797 | E24: =IFERROR(E17/E6,0) -> 0.1930283 | F24: =IFERROR(F17/F6,0) -> 0.20355733
A25: שולי EBITDA % (Y2) | B25: שנה 2 | C25: EBITDA ÷ הכנסות B2B | D25: =IFERROR(D18/D7,0) -> 0.16340035 | E25: =IFERROR(E18/E7,0) -> 0.21478205 | F25: =IFERROR(F18/F7,0) -> 0.21736129
A26: חודש Break-even (משוער) | B26: Y1-Y2 | C26: אומדן — תלוי ב-ramp | D26: =IFERROR(-D16/((D14+D15)/24),0) -> 0.61583108 | E26: =IFERROR(-E16/((E14+E15)/24),0) -> 1.0743471 | F26: =IFERROR(-F16/((F14+F15)/24),0) -> 0.76655029
A28: C. מסקנות מהמודל — השוואה בין הפורמטים
A29: המודל מניח כל פורמט כתרחיש עצמאי המקבל את מלוא תקציב השיווק (₪750K). פורמט 150g (בעל white space + צמיחה +113%) צפוי לייצר את ה-EBITDA הגבוה ביותר בשנה 2. פורמט 3×100g מייצר הכנסות גבוהות יותר בזכות ASP גבוה (₪19.50/מארז) אבל תחת מרווחים דומים. פורמט 100g חיובי בהכנסה אך תחת לחץ תחרותי — דורש מיצוב מחיר אגרסיבי. המלצה: להתחיל עם 150g, להוסיף 3×100g ב-M7, ולשקול 100g בשנה 2 לאחר ביסוס המותג.

Sheet השוואה
A1: השוואה ישירה — 3 פורמטים · KPIs מרכזיים
A2: כל תא מקושר לתחזיות ולהנחות · השינויים בהנחות ישנו את כל ההשוואה
A4: A. פרמטרי מוצר
A5: מדד | B5: תיאור | D5: 150g | E5: 3×100g | F5: 100g
A6: מחיר B2B | B6: מחיר לחשבונית למפיץ | D6: =הנחות!$B$41 -> 8.9 | E6: =הנחות!$B$46 -> 19.5 | F6: =הנחות!$B$51 -> 6.5
A7: עלות ייצור | B7: COGS לפורמט | D7: =הנחות!$B$7 -> 5.805 | E7: =הנחות!$B$8 -> 11.61 | F7: =הנחות!$B$9 -> 3.87
A8: מחיר מדף B2C (שוק פרטי) | B8: B2B ÷ (1-20%) × (1+18%) | D8: =הנחות!$B$41/(1-הנחות!$B$15)*(1+הנחות!$B$13) -> 13.1275 | E8: =הנחות!$B$46/(1-הנחות!$B$15)*(1+הנחות!$B$13) -> 28.7625 | F8: =הנחות!$B$51/(1-הנחות!$B$15)*(1+הנחות!$B$13) -> 9.5875
A9: מחיר ל-100g (נורמלי) | B9: מחיר מדף ÷ גרם-100 שווה-ערך | D9: =(הנחות!$B$41/(1-הנחות!$B$15)*(1+הנחות!$B$13))/1.5 -> 8.7516667 | E9: =(הנחות!$B$46/(1-הנחות!$B$15)*(1+הנחות!$B$13))/3 -> 9.5875 | F9: =הנחות!$B$51/(1-הנחות!$B$15)*(1+הנחות!$B$13) -> 9.5875
A10: רווח גולמי ליחידה | B10: הכנסות נטו − COGS | D10: =הנחות!$B$41*(1-הנחות!$B$16)-הנחות!$B$7 -> 1.493 | E10: =הנחות!$B$46*(1-הנחות!$B$16)-הנחות!$B$8 -> 4.38 | F10: =הנחות!$B$51*(1-הנחות!$B$16)-הנחות!$B$9 -> 1.46
A11: GM% ליחידה | B11: GP ÷ מחיר B2B | D11: =(הנחות!$B$41*(1-הנחות!$B$16)-הנחות!$B$7)/הנחות!$B$41 -> 0.16775281 | E11: =(הנחות!$B$46*(1-הנחות!$B$16)-הנחות!$B$8)/הנחות!$B$46 -> 0.22461538 | F11: =(הנחות!$B$51*(1-הנחות!$B$16)-הנחות!$B$9)/הנחות!$B$51 -> 0.22461538
A13: B. יעדים ותחזית — נתח שוק + הכנסות
A14: מדד | B14: תיאור | D14: 150g | E14: 3×100g | F14: 100g
A15: יעד נתח שוק M12 | B15: נתח מיעד — סוף שנה 1 | D15: =הנחות!$B$43 -> 0.15 | E15: =הנחות!$B$48 -> 0.07 | F15: =הנחות!$B$53 -> 0.09
A16: יעד נתח שוק M24 | B16: נתח מיעד — סוף שנה 2 | D16: =הנחות!$B$43 -> 0.15 | E16: =הנחות!$B$48 -> 0.07 | F16: =הנחות!$B$53 -> 0.09
A17: הכנסות B2B — שנה 1 | B17: מתחזית חודשית (SUM M1-M12) | D17: ='תחזית 150 גרם'!F31 -> 17807910 | E17: ='תחזית 3x100 גרם'!F31 -> 7123163.8 | F17: ='תחזית 100 גרם'!F31 -> 10684746
A18: הכנסות B2B — שנה 2 | B18: מתחזית חודשית (SUM M13-M24) | D18: ='תחזית 150 גרם'!F56 -> 34463277 | E18: ='תחזית 3x100 גרם'!F56 -> 15254237 | F18: ='תחזית 100 גרם'!F56 -> 20677966
A19: יחידות — שנה 1 | B19: מתחזית חודשית | D19: ='תחזית 150 גרם'!E31 -> 2000888.7 | E19: ='תחזית 3x100 גרם'!E31 -> 365290.45 | F19: ='תחזית 100 גרם'!E31 -> 1643807
A20: יחידות — שנה 2 | B20: מתחזית חודשית | D20: ='תחזית 150 גרם'!E56 -> 3872278.3 | E20: ='תחזית 3x100 גרם'!E56 -> 782268.58 | F20: ='תחזית 100 גרם'!E56 -> 3181225.6
A21: רווח גולמי — שנה 1 | B21: מתחזית חודשית | D21: ='תחזית 150 גרם'!I31 -> 2987326.9 | E21: ='תחזית 3x100 גרם'!I31 -> 1599972.2 | F21: ='תחזית 100 גרם'!I31 -> 2399958.3
A22: רווח גולמי — שנה 2 | B22: מתחזית חודשית | D22: ='תחזית 150 גרם'!I56 -> 5781311.5 | E22: ='תחזית 3x100 גרם'!I56 -> 3426336.4 | F22: ='תחזית 100 גרם'!I56 -> 4644589.3
A24: C. EBITDA + צמיחה Y2 vs Y1
A25: מדד | B25: תיאור | D25: 150g | E25: 3×100g | F25: 100g
A26: EBITDA — שנה 1 | B26: רווח גולמי − שיווק (Raito) | D26: ='רווח והפסד'!D17 -> 2762326.9 | E26: ='רווח והפסד'!E17 -> 1374972.2 | F26: ='רווח והפסד'!F17 -> 2174958.3
A27: EBITDA — שנה 2 | B27: רווח גולמי Y2 − שיווק Y2 | D27: ='רווח והפסד'!D18 -> 5631311.5 | E27: ='רווח והפסד'!E18 -> 3276336.4 | F27: ='רווח והפסד'!F18 -> 4494589.3
A28: EBITDA — סה״כ 2 שנים | B28: סיכום 24 חודשים | D28: ='רווח והפסד'!D19 -> 8393638.4 | E28: ='רווח והפסד'!E19 -> 4651308.6 | F28: ='רווח והפסד'!F19 -> 6669547.6
A29: צמיחת הכנסות Y2/Y1 | B29: (Y2-Y1)/Y1 | D29: =('תחזית 150 גרם'!F56-'תחזית 150 גרם'!F31)/'תחזית 150 גרם'!F31 -> 0.93527919 | E29: =('תחזית 3x100 גרם'!F56-'תחזית 3x100 גרם'!F31)/'תחזית 3x100 גרם'!F31 -> 1.1414975 | F29: =('תחזית 100 גרם'!F56-'תחזית 100 גרם'!F31)/'תחזית 100 גרם'!F31 -> 0.93527919
A31: D. חוזקות וחולשות — תמצית
A32: פורמט | B32: חוזקות | D32: חולשות | F32: ציון
A33: 150g | B33: White space ב-CHP (8/94 רשתות בלבד), צמיחה +113%, סגמנט חדש בתמחור נוח | D33: הפצה מוגבלת בהתחלה — דורש השקעה בבניית distribution | F33: 9/10 — מומלץ ביותר
A34: 3×100g | B34: מצטרף לטרנד המארזים החדשים (98×3, 4×115g), ASP גבוה, ערך-למחיר | D34: תחרות מ-3×85g של Elite (₪24.46), דורש מיקום ברור — משפחות/ערך | F34: 7.5/10 — מומלץ כהשלמה
A35: 100g | B35: הסגמנט הגדול ביותר (~7% נתח), פורמט מוכר, הזדמנות לפריצה במחיר | D35: Elite ב-70% רשתות, מחיר נמוך יותר דורש נפח; הסגמנט בירידה של -3.7% YTD | F35: 6/10 — דחייה לשנה 2

Sheet תקציב שיווק
A1: אסטרטגיית שיווק — 24 חודשים · תקציב ₪750K (50/50 Raito/Ma Kashur)
A2: אסטרטגיית Ma Kashur: אורגני, משפיענים, תוכן — לא מדיה משלמת מס
A4: A. סך התקציב והחלוקה בין השותפים
A5: פריט | B5: ערך | C5: הערות
A6: סה״כ תקציב 24 חודשים | B6: =הנחות!$B$32 -> 750000 | C6: קלט מהנחות — ניתן לשינוי בין ₪500K–₪1M
A7: חלק Raito | B7: =הנחות!$B$32*הנחות!$B$33 -> 375000 | C7: 50% שוויוני — מומן על ידי Raito
A8: חלק Ma Kashur | B8: =הנחות!$B$32*הנחות!$B$34 -> 375000 | C8: 50% שוויוני — מומן על ידי Ma Kashur (שותפות אסטרטגית)
A9: תקציב ממוצע חודשי | B9: =הנחות!$B$32/24 -> 31250 | C9: פיזור שווה — בפועל פרונט-loaded
A10: תקציב שנה 1 (60%) | B10: =הנחות!$B$32*0.6 -> 450000 | C10: השקה כבדה — בניית מודעות למותג
A11: תקציב שנה 2 (40%) | B11: =הנחות!$B$32*0.4 -> 300000 | C11: תחזוקה + הרחבה
A13: B. חלוקת התקציב לפי ערוץ (אסטרטגיית Ma Kashur — אורגני-ממומן)
A14: ערוץ | B14: אחוז | C14: ₪ 24 חודשים | D14: ₪ חודשי ממוצע | E14: תיאור ופעילויות
A15: משפיענים (Ma Kashur ecosystem) | B15: 0.35 | C15: =הנחות!$B$32*B15 -> 262500 | D15: =C15/24 -> 10937.5 | E15: שיתופי פעולה עם משפיענים ערבים-ישראלים בתחומי אוכל/חיי בית — 15-20 תכנים בחודש
A16: תוכן מותגי (Ma Kashur studio) | B16: 0.2 | C16: =הנחות!$B$32*B16 -> 150000 | D16: =C16/24 -> 6250 | E16: תוכן וידאו/פוסטים/רילס — סיפור המותג, היסטוריה, טעימות
A17: PR + עיתונות (כלכליסט, ynet, The Marker) | B17: 0.1 | C17: =הנחות!$B$32*B17 -> 75000 | D17: =C17/24 -> 3125 | E17: קמפיין PR בהשקה — סטורי על Raito + מוצר ערבי-ישראלי אמתי
A18: דגימות + קידום בנקודת מכירה | B18: 0.15 | C18: =הנחות!$B$32*B18 -> 112500 | D18: =C18/24 -> 4687.5 | E18: דוכני דגימה ברשתות + אירועים מיוחדים במגזר הערבי
A19: דיגיטלי — Meta + TikTok | B19: 0.1 | C19: =הנחות!$B$32*B19 -> 75000 | D19: =C19/24 -> 3125 | E19: קמפיינים ממוקדים — ספקטרום דמוגרפי: 25-55, הן במגזר הערבי והן יהודי סקרני
A20: Events + שותפויות (ראמדאן, חגים, פסטיבלים) | B20: 0.07 | C20: =הנחות!$B$32*B20 -> 52500 | D20: =C20/24 -> 2187.5 | E20: נוכחות באירועים במגזר הערבי — דרום תל אביב, נצרת, חיפה
A21: Reserve / התאמה לתרחיש | B21: 0.03 | C21: =הנחות!$B$32*B21 -> 22500 | D21: =C21/24 -> 937.5 | E21: רזרבה לתגובה לתחרות, הזדמנויות לא צפויות
A22: סה״כ — בדיקה | B22: =SUM(B15:B21) -> 1 | C22: =SUM(C15:C21) -> 750000 | D22: =SUM(D15:D21) -> 31250 | E22: אמור להיות 100% ו- 100% מהתקציב הכולל
A24: C. לוח זמנים — פילוח לפי פאזה
A25: פאזה | B25: חודשים | C25: % מהתקציב | D25: ₪ | E25: פעילות מרכזית
A26: שלב 1 — השקה | B26: M1-M6 | C26: 0.4 | D26: =הנחות!$B$32*C26 -> 300000 | E26: PR blitz, משפיענים גדולים, PR השקה, דוכני דגימה ברשתות מובילות
A27: שלב 2 — הרחבה | B27: M7-M18 | C27: 0.4 | D27: =הנחות!$B$32*C27 -> 300000 | E27: המשך משפיענים קבועים, קמפיינים עונתיים (קיץ, רמדאן, חגים), שותפויות
A28: שלב 3 — בגרות | B28: M19-M24 | C28: 0.2 | D28: =הנחות!$B$32*C28 -> 150000 | E28: תחזוקה, מוצרי המשך (טעמים/פורמטים), דיגיטלי ממוקד ROI
A30: D. KPIs לתקציב השיווק — מה נמדוד?
A31: Reach | B31: חשיפות בתקופה | D31: 5M+ חשיפות באוכלוסיית היעד (מגזר ערבי + קהל כללי סקרן)
A32: Brand Awareness (AI/AD) | B32: סקר ייעודי — רבעוני | D32: מ-0% ל-25% ביצועי זיהוי מותג (aided) באוכלוסיית היעד עד M12
A33: CAC (Cost per Acquisition) | B33: ₪ למוצר שנמכר | D33: ₪15-25 ל-unit נרכש — בהתאם לערוצים
A34: Conversion משפיענים | B34: % ממעקב לרכישה | D34: 1.5-3% conversion מצפייה להוספה לסל
A35: Distribution build | B35: רשתות / חנויות בשוק פרטי | D35: Y1: 30 חנויות עצמאיות ראשונות, 1-2 רשתות מאורגנות; Y2: הרחבה
A36: Velocity per store | B36: יחידות/חנות/שבוע | D36: יעד M6: 10+ יח׳/שבוע/חנות; M12: 20+ יח׳/שבוע/חנות
