Workbook

Sheet Assumptions
A1: TURBO x SUPER-PHARM — MODEL ASSUMPTIONS (formula-driven)
A2: Blue cells = inputs | Black cells = calculated | All other sheets update automatically when you change inputs here
A4: A. PRODUCT PORTFOLIO
A5: Product | B5: Spec | C5: Value | D5: Unit | E5: Notes
A6: Protein Powder | B6: Protein per serving | C6: 24 | D6: g | E6: Daily performance anchor
B7: Creatine content | C7: 1.5 | D7: g | E7: Performance enhancer
B8: Brand / Supplier | C8: Maolac | E8: Premium source
B9: Servings per pack | C9: 24 | D9: servings | E9: Single-month supply
B10: Pack size | C10: 760–800 | D10: g | E10: Premium positioning
A11: Protein Bars | B11: Weight per bar | C11: 55–60 | D11: g | E11: Portable, convenient
B12: Protein per bar | C12: 16–18 | D12: g | E12: Balanced macros
A13: Protein Chocolate | B13: Weight per bar | C13: 38 | D13: g | E13: Impulse size
B14: Protein per bar | C14: 10–12 | D14: g | E14: Functional indulgence
B15: Calories per bar | C15: ≤150 | D15: cal | E15: Guilt-free luxury
A17: B. PRICING — B2C Retail (including VAT)
A18: Product | B18: MSRP | C18: Effective Average | D18: Unit | E18: Notes
A19: Protein Powder | B19: 159.9 | C19: 149.9 | D19: ₪/unit | E19: Premium positioning at Super-Pharm
A20: Protein Bars | B20: 13.9 | C20: 12.9 | D20: ₪/unit | E20: Impulse price point
A21: Protein Chocolate | B21: 14.9 | C21: 14.2 | D21: ₪/unit | E21: Mid-range impulse, premium quality
A23: C. ROYALTY MODEL
A24: Parameter | B24: Value | C24: Unit | D24: Notes
A25: Raito royalty rate on retail sales | B25: 0.07 | C25: % | D25: Applied to 100% B2C retail revenue
A27: D. SKU EXPANSION ROADMAP
A28: Phase | B28: Powder | C28: Bars | D28: Chocolate | E28: Total SKUs
A29: Year 1 — Launch | B29: 3 | C29: 3 | D29: 3 | E29: =B29+C29+D29
A31: Year 2 — Range Expansion | B31: 5 | C31: 5 | D31: 4 | E31: =B31+C31+D31
A32: Year 3 — Platform | B32: 7 | C32: 7 | D32: 4 | E32: =B32+C32+D32
A34: E. EXCLUSIVITY STRUCTURE
A35: Category | B35: Channel | C35: Scope | D35: Strategic Implication
A36: Protein Powder | B36: Super-Pharm ONLY | C36: 100% exclusive | D36: Category ownership — daily driver
A37: Protein Bars | B37: Super-Pharm ONLY | C37: 100% exclusive | D37: Volume & frequency play
A38: Protein Chocolate | B38: Super-Pharm first | C38: 2 exclusive + 2 mass | D38: Innovation + mass scale option
A40: F. SALES FORECAST — GOOD CASE (B2C Retail, ₪ Millions)
A41: Category | B41: Year 1 | C41: Year 2 | D41: Year 3 | E41: Notes
A42: Protein Powder | B42: 18 | C42: 23 | D42: 28 | E42: Premium positioning, high ASP
A43: Protein Bars | B43: 7 | C43: 10 | D43: 13 | E43: Volume & impulse driver
A44: Protein Chocolate | B44: 4.5 | C44: 6.5 | D44: 8.5 | E44: New category, innovation
A45: TOTAL — GOOD CASE | B45: =B42+B43+B44 | C45: =C42+C43+C44 | D45: =D42+D43+D44
A47: G. SALES FORECAST — IDEAL CASE (B2C Retail, ₪ Millions)
A48: Category | B48: Year 1 | C48: Year 2 | D48: Year 3 | E48: Notes
...

Sheet Sales Forecast
A1: TURBO x SUPER-PHARM — RETAIL SALES FORECAST (B2C)
A2: Three-year platform build: Good Case (₪29.5M → ₪39.5M → ₪49.5M) | Ideal Case (₪39M → ₪52.5M → ₪67M) | All formulas reference Assumptions
A4: SCENARIO 1: GOOD CASE
A5: Category | B5: Year 1 | C5: Year 2 | D5: Year 3 | E5: 3-Year Total
A6: Protein Powder | B6: =Assumptions!$B$42 | C6: =Assumptions!$C$42 | D6: =Assumptions!$D$42 | E6: =B6+C6+D6
A7: Protein Bars | B7: =Assumptions!$B$43 | C7: =Assumptions!$C$43 | D7: =Assumptions!$D$43 | E7: =B7+C7+D7
A8: Protein Chocolate | B8: =Assumptions!$B$44 | C8: =Assumptions!$C$44 | D8: =Assumptions!$D$44 | E8: =B8+C8+D8
A9: TOTAL — GOOD CASE | B9: =SUM(B6:B8) | C9: =SUM(C6:C8) | D9: =SUM(D6:D8) | E9: =SUM(E6:E8)
A11: SCENARIO 2: IDEAL CASE
A12: Category | B12: Year 1 | C12: Year 2 | D12: Year 3 | E12: 3-Year Total
A13: Protein Powder | B13: =Assumptions!$B$49 | C13: =Assumptions!$C$49 | D13: =Assumptions!$D$49 | E13: =B13+C13+D13
A14: Protein Bars | B14: =Assumptions!$B$50 | C14: =Assumptions!$C$50 | D14: =Assumptions!$D$50 | E14: =B14+C14+D14
A15: Protein Chocolate | B15: =Assumptions!$B$51 | C15: =Assumptions!$C$51 | D15: =Assumptions!$D$51 | E15: =B15+C15+D15
A16: TOTAL — IDEAL CASE | B16: =SUM(B13:B15) | C16: =SUM(C13:C15) | D16: =SUM(D13:D15) | E16: =SUM(E13:E15)

Sheet Royalty Revenue
A1: TURBO x SUPER-PHARM — ROYALTY REVENUE TO RAITO (7%)
A2: Raito receives 7% royalty on all B2C retail sales | Per-SKU analysis shows revenue per individual SKU across product categories and years
A4: SCENARIO 1: GOOD CASE ROYALTIES
A5: Category | B5: Year 1 | C5: Year 2 | D5: Year 3 | E5: 3-Year Total | F5: SKU Count Y3
A6: Protein Powder | B6: =Assumptions!$B$42*Assumptions!$B$25 | C6: =Assumptions!$C$42*Assumptions!$B$25 | D6: =Assumptions!$D$42*Assumptions!$B$25 | E6: =B6+C6+D6 | F6: =Assumptions!$B$32
A7: Protein Bars | B7: =Assumptions!$B$43*Assumptions!$B$25 | C7: =Assumptions!$C$43*Assumptions!$B$25 | D7: =Assumptions!$D$43*Assumptions!$B$25 | E7: =B7+C7+D7 | F7: =Assumptions!$C$32
A8: Protein Chocolate | B8: =Assumptions!$B$44*Assumptions!$B$25 | C8: =Assumptions!$C$44*Assumptions!$B$25 | D8: =Assumptions!$D$44*Assumptions!$B$25 | E8: =B8+C8+D8 | F8: =Assumptions!$D$32
A9: TOTAL ROYALTY — GOOD CASE | B9: =SUM(B6:B8) | C9: =SUM(C6:C8) | D9: =SUM(D6:D8) | E9: =B9+C9+D9
A11: SCENARIO 2: IDEAL CASE ROYALTIES
A12: Category | B12: Year 1 | C12: Year 2 | D12: Year 3 | E12: 3-Year Total | F12: SKU Count Y3
A13: Protein Powder | B13: =Assumptions!$B$49*Assumptions!$B$25 | C13: =Assumptions!$C$49*Assumptions!$B$25 | D13: =Assumptions!$D$49*Assumptions!$B$25 | E13: =B13+C13+D13 | F13: =Assumptions!$B$32
A14: Protein Bars | B14: =Assumptions!$B$50*Assumptions!$B$25 | C14: =Assumptions!$C$50*Assumptions!$B$25 | D14: =Assumptions!$D$50*Assumptions!$B$25 | E14: =B14+C14+D14 | F14: =Assumptions!$C$32
A15: Protein Chocolate | B15: =Assumptions!$B$51*Assumptions!$B$25 | C15: =Assumptions!$C$51*Assumptions!$B$25 | D15: =Assumptions!$D$51*Assumptions!$B$25 | E15: =B15+C15+D15 | F15: =Assumptions!$D$32
A16: TOTAL ROYALTY — IDEAL CASE | B16: =SUM(B13:B15) | C16: =SUM(C13:C15) | D16: =SUM(D13:D15) | E16: =B16+C16+D16

Sheet SKU Roadmap
A1: TURBO x SUPER-PHARM — SKU EXPANSION ROADMAP
A2: Platform strategy: 3-year SKU expansion from 9 → 14 → 18 SKUs | Exclusive positioning at Super-Pharm across all categories
A4: SKU EXPANSION TIMELINE
A5: Phase | B5: Powder SKUs | C5: Bars SKUs | D5: Chocolate SKUs | E5: Total SKUs | F5: Strategy | G5: Notes
A6: Year 1 Launch | B6: 3 | C6: 3 | D6: 3 | E6: 9 | F6: Category entry | G6: Foundation: proven formulas in Powder (daily), Bars (impulse), Chocolate (innovation)
A7: Year 2 Range Expansion | B7: 5 | C7: 5 | D7: 4 | E7: 14 | F7: Portfolio depth | G7: Add flavors, formats, sizes. Powder: variants. Bars: textures. Chocolate: premium line.
A8: Year 3 Platform | B8: 7 | C8: 7 | D8: 4 | E8: 18 | F8: Market dominance | G8: Consolidate Powder/Bars, stabilize Chocolate. Position as trusted lifestyle brand.
A10: EXCLUSIVITY STRUCTURE
A11: Category | B11: Super-Pharm Status | C11: Mass Market Option | D11: Strategic Implication | E11: Launch Priority
A12: Protein Powder | B12: Exclusive | C12: None — locked to SP | D12: Premium daily driver, category ownership | E12: Year 1
A13: Protein Bars | B13: Exclusive | C13: None — locked to SP | D13: Frequency & volume anchor, impulse | E13: Year 1
A14: Protein Chocolate | B14: Super-Pharm First | C14: 2 SKUs available later | D14: Innovation + scale optionality | E14: Year 1
A16: REVENUE PER SKU ANALYSIS (Good Case)
A17: Category | B17: Year 1 Revenue | C17: Y1 SKU Count | D17: Revenue/SKU Y1 | E17: Year 3 Revenue | F17: Y3 SKU Count | G17: Revenue/SKU Y3
A18: Protein Powder | B18: =Assumptions!$B$42 | C18: =Assumptions!$B$29 | D18: =B18/C18 | E18: =Assumptions!$D$42 | F18: =Assumptions!$B$32 | G18: =E18/F18
A19: Protein Bars | B19: =Assumptions!$B$43 | C19: =Assumptions!$C$29 | D19: =B19/C19 | E19: =Assumptions!$D$43 | F19: =Assumptions!$C$32 | G19: =E19/F19
A20: Protein Chocolate | B20: =Assumptions!$B$44 | C20: =Assumptions!$D$29 | D20: =B20/C20 | E20: =Assumptions!$D$44 | F20: =Assumptions!$D$32 | G20: =E20/F20

Sheet Strategic Analysis
A1: TURBO x SUPER-PHARM — STRATEGIC ANALYSIS
A2: Category ownership platform, not just licensing. Three consumption moments. Genuine exclusivity. Deni Avdija as brand ambassador.
A4: A. THE STRATEGIC THESIS
A5: Category Ownership, Not Just Licensing | B5: Turbo builds a complete protein lifestyle portfolio at Super-Pharm — not individual products. Three consumption moments map to three categories: Powder (daily routine, trust, performance); Bars (on-the-go, frequency, impulse); Chocolate (indulgence, innovation, new consumer acquisition).
A6: Exclusivity Creates Real Value | B6: Powder and Bars are locked to Super-Pharm; Chocolate is first-mover advantage. This exclusivity is defensible — no other partner can offer the full stack. Retailers outside SP cannot compete on the platform.
A7: Brand Pull from Deni Avdija | B7: The celebrity ambassador is the engine. Consumers buy Turbo FOR Deni, not in spite of premium pricing. This pull justifies the premium ASP and justifies Super-Pharm shelf space allocation versus competing brands.
A8: Platform Synergy Across Categories | B8: Powder builds trust and category awareness. Bars drive frequency and basket size. Chocolate drives innovation perception and acquisition of non-protein consumers. Each category strengthens the others within the same platform.
A10: B. PARTNERSHIP PRINCIPLES
A11: ► Super-Pharm as Strategic Partner (not just retailer) | B11: This is a co-owned platform, not vendor-retail. SP is not a distribution channel — it's the exclusive channel. The partnership lives or dies on SP's willingness to allocate space and drive consumer pull.
A12: ► Genuine Exclusivity Creates Value | B12: Powder and Bars cannot go to Shufersal, Mega, or independents. Chocolate has optionality for controlled expansion. This lock-in is non-negotiable — it's the core of why SP signs the deal.
A13: ► Exceptional Brand Pull (Deni Avdija as Lever) | B13: Deni is the contract. His social media reach, personal brand, and fitness credibility drive consumer desire. Every product is positioned as 'Deni's choice.' Without him, the model collapses.
A14: ► Category Expansion, Not Just Demand Redistribution | B14: This is not a zero-sum game. Protein at Super-Pharm is growing. Turbo is expanding the category, not stealing from Elite or GoNutrition. Good Case assumes 3-year growth; Ideal assumes viral adoption on Deni momentum.
A16: C. WHY THE IDEAL CASE IS JUSTIFIED
A17: ► Deni Factor | B17: Deni Avdija is an elite Israeli athlete with significant social media pull. His endorsement drives awareness and trial unlike generic celebrity partnerships. If content + placement perform, viral adoption is plausible.
A18: ► Category Momentum | B18: Protein supplements are growing 15–20% annually in Israel. Turbo enters at the right moment with premium positioning and exclusive distribution. There is no ceiling — only distribution and marketing constraints.
A19: ► Super-Pharm Commitment | B19: SP is investing in the platform with prominent shelf space, point-of-sale, and in-store sampling. If they execute the marketing plan, Ideal Case numbers are achievable within 3 years.
A20: ► Portfolio Strength | B20: Three products create a self-reinforcing loop: Powder drives category, Bars drive frequency, Chocolate drives trial. This is not a single-SKU launch — it's a portfolio play.
A22: D. CRITICAL SUCCESS FACTORS
A23: ► 1. Deni Content & Engagement | B23: Weekly social media posts, in-store appearances, YouTube content. Deni must be visible and authentic in the product ecosystem. This is non-delegable.
A24: ► 2. Super-Pharm In-Store Execution | B24: Prominent shelf space, sampling programs, trained staff, point-of-sale materials. SP must treat Turbo as strategic, not commodity. This requires board-level alignment.
A25: ► 3. Product Quality & Consistency | B25: No shortcuts on taste, nutrition, or supply chain. A single bad batch destroys the premium brand. Raito must oversee supplier QA.
A26: ► 4. Distribution Velocity | B26: Launch in all 100+ SP stores within 60 days. Partial rollouts = failure. Deni momentum is time-limited. First-mover advantage expires quickly.
A27: ► 5. Consumer Retention Beyond Trial | B27: Acquisition is expensive. Repeat purchase rate must exceed 40% within 6 months. This requires a loyalty program or community ( potential Trio Coffee Parliament model for Turbo).
A29: E. PORTFOLIO SYNERGY
A30: ► Powder: The Trust Anchor | B30: 24g protein, creatine, Maolac supply. Daily routine. Builds category authority and consumer trust in the Turbo brand. Commands premium ASP (₪149.90). High margin. Locks loyalty.
A31: ► Bars: The Frequency Driver | B31: 55–60g bars, 16–18g protein. On-the-go convenience. Impulse buys at checkout. Lower ASP than Powder but much higher velocity. Creates repeat basket and upsells to Powder.
A32: ► Chocolate: The Acquisition Play | B32: 38g, 10–12g protein, ≤150 cal. Non-traditional protein consumer. 'Indulgence first, nutrition second' positioning. Innovation signal. Optionality for mass-market expansion post-year-2.

Sheet Executive Summary
A1: TURBO x SUPER-PHARM — EXECUTIVE SUMMARY
A2: 3-year protein lifestyle platform with Deni Avdija. Exclusive at Super-Pharm. 7% royalty to Raito. Two scenarios presented below.
A4: KEY METRICS AT A GLANCE
A5: Metric | B5: Good Case | C5: Ideal Case | D5: Difference | E5: Key Insight
A6: Year 1 B2C Retail (₪M) | B6: =Assumptions!B45 | C6: =Assumptions!B52 | D6: =C6-B6 | E6: Ideal = 32% higher initial penetration
A7: Year 3 B2C Retail (₪M) | B7: =Assumptions!D45 | C7: =Assumptions!D52 | D7: =C7-B7 | E7: Ideal = 35% higher mature state
A9: RAITO ROYALTY REVENUE (7%)
A10: Metric | B10: Good Case | C10: Ideal Case | D10: Unit | E10: Commentary
A11: Year 1 Royalty | B11: =Assumptions!B45*Assumptions!$B$25 | C11: =Assumptions!B52*Assumptions!$B$25 | D11: ₪ | E11: Launch year royalty
A12: Year 3 Royalty | B12: =Assumptions!D45*Assumptions!$B$25 | C12: =Assumptions!D52*Assumptions!$B$25 | D12: ₪ | E12: Mature year royalty
A13: 3-Year Cumulative Royalty | B13: =(Assumptions!B45+Assumptions!C45+Assumptions!D45)*Assumptions!$B$25 | C13: =(Assumptions!B52+Assumptions!C52+Assumptions!D52)*Assumptions!$B$25 | D13: ₪ | E13: Platform lifetime royalty
A16: PLATFORM POSITIONING
A17: ► WHAT IT IS | B17: Not a single-product launch. A complete protein lifestyle ecosystem with 9–18 SKUs across three consumption moments. Deni Avdija is the brand anchor.
A18: ► WHY IT WORKS | B18: Exclusivity + premium positioning + celebrity pull + synergistic portfolio. Powder builds trust, Bars drive frequency, Chocolate drives trial. Each strengthens the others.
A19: ► PARTNERSHIP FOCUS | B19: Super-Pharm is not a retailer — it's a co-owner. Raito earns 7% of B2C sales. SP benefits from exclusive category lock-in and Deni's brand pull. Win-win.
A20: ► SUCCESS DEPENDS ON | B20: Deni's authentic engagement, SP's in-store execution, product quality, and rapid distribution velocity. All four must align for Ideal Case to materialize.
A22: BOTTOM LINE: We're not building a licensing deal. We're building the first Turbo platform in Israel with Super-Pharm as strategic co-owner. Deni drives demand. Exclusive distribution creates defensibility. 7% royalty scales with retail growth.
